2023-07-17 15:30:03,270 - discord.client - INFO - logging in using static token
2023-07-17 15:30:04,924 - discord.gateway - INFO - Shard ID None has connected to Gateway (Session ID: 2e91f616aad6045be79a95772aef159c).
2023-07-17 15:30:07,041 - root - INFO - Logged in as Anigay 2.0#7825
2023-07-17 15:30:11,383 - discord.ext.commands.bot - ERROR - Ignoring exception in command summon
Traceback (most recent call last):
  File "/home/iceman/.local/lib/python3.10/site-packages/discord/ext/commands/core.py", line 235, in wrapped
    ret = await coro(*args, **kwargs)
  File "/home/iceman/___/Anigay-2.0/src/Dev.py", line 37, in summon
    await cursor.execute("SELECT * FROM Users WHERE id=?", (user_id,))
  File "/home/iceman/.local/lib/python3.10/site-packages/asqlite/__init__.py", line 210, in execute
    await self._post(self._cursor.execute, sql, parameters)
  File "/home/iceman/.local/lib/python3.10/site-packages/asqlite/__init__.py", line 85, in _call_entry
    result = entry.func(*entry.args, **entry.kwargs)
sqlite3.OperationalError: no such table: Users

The above exception was the direct cause of the following exception:

Traceback (most recent call last):
  File "/home/iceman/.local/lib/python3.10/site-packages/discord/ext/commands/bot.py", line 1350, in invoke
    await ctx.command.invoke(ctx)
  File "/home/iceman/.local/lib/python3.10/site-packages/discord/ext/commands/core.py", line 1029, in invoke
    await injected(*ctx.args, **ctx.kwargs)  # type: ignore
  File "/home/iceman/.local/lib/python3.10/site-packages/discord/ext/commands/core.py", line 244, in wrapped
    raise CommandInvokeError(exc) from exc
discord.ext.commands.errors.CommandInvokeError: Command raised an exception: OperationalError: no such table: Users
2023-07-17 15:30:41,921 - discord.client - INFO - logging in using static token
2023-07-17 15:30:43,212 - discord.gateway - INFO - Shard ID None has connected to Gateway (Session ID: 9c54ff9462970e013efeebc00f68fa8c).
2023-07-17 15:30:45,307 - root - INFO - Logged in as Anigay 2.0#7825
2023-07-17 15:30:50,283 - discord.ext.commands.bot - ERROR - Ignoring exception in command summon
Traceback (most recent call last):
  File "/home/iceman/.local/lib/python3.10/site-packages/discord/ext/commands/core.py", line 235, in wrapped
    ret = await coro(*args, **kwargs)
  File "/home/iceman/___/Anigay-2.0/src/Dev.py", line 37, in summon
    await cursor.execute("SELECT * FROM Users WHERE id=?", (user_id,))
  File "/home/iceman/.local/lib/python3.10/site-packages/asqlite/__init__.py", line 210, in execute
    await self._post(self._cursor.execute, sql, parameters)
  File "/home/iceman/.local/lib/python3.10/site-packages/asqlite/__init__.py", line 85, in _call_entry
    result = entry.func(*entry.args, **entry.kwargs)
sqlite3.OperationalError: no such table: Users

The above exception was the direct cause of the following exception:

Traceback (most recent call last):
  File "/home/iceman/.local/lib/python3.10/site-packages/discord/ext/commands/bot.py", line 1350, in invoke
    await ctx.command.invoke(ctx)
  File "/home/iceman/.local/lib/python3.10/site-packages/discord/ext/commands/core.py", line 1029, in invoke
    await injected(*ctx.args, **ctx.kwargs)  # type: ignore
  File "/home/iceman/.local/lib/python3.10/site-packages/discord/ext/commands/core.py", line 244, in wrapped
    raise CommandInvokeError(exc) from exc
discord.ext.commands.errors.CommandInvokeError: Command raised an exception: OperationalError: no such table: Users
2023-07-17 15:31:19,028 - discord.client - INFO - logging in using static token
2023-07-17 15:31:19,966 - discord.gateway - INFO - Shard ID None has connected to Gateway (Session ID: 3e77ce161ed6a5db42395f1d4a064fae).
2023-07-17 15:31:22,073 - root - INFO - Logged in as Anigay 2.0#7825
2023-07-17 15:31:25,556 - discord.ext.commands.bot - ERROR - Ignoring exception in command summon
Traceback (most recent call last):
  File "/home/iceman/.local/lib/python3.10/site-packages/discord/ext/commands/core.py", line 235, in wrapped
    ret = await coro(*args, **kwargs)
  File "/home/iceman/___/Anigay-2.0/src/Dev.py", line 37, in summon
    await cursor.execute("SELECT * FROM Users WHERE id=?", (user_id,))
  File "/home/iceman/.local/lib/python3.10/site-packages/asqlite/__init__.py", line 210, in execute
    await self._post(self._cursor.execute, sql, parameters)
  File "/home/iceman/.local/lib/python3.10/site-packages/asqlite/__init__.py", line 85, in _call_entry
    result = entry.func(*entry.args, **entry.kwargs)
sqlite3.OperationalError: no such table: Users

The above exception was the direct cause of the following exception:

Traceback (most recent call last):
  File "/home/iceman/.local/lib/python3.10/site-packages/discord/ext/commands/bot.py", line 1350, in invoke
    await ctx.command.invoke(ctx)
  File "/home/iceman/.local/lib/python3.10/site-packages/discord/ext/commands/core.py", line 1029, in invoke
    await injected(*ctx.args, **ctx.kwargs)  # type: ignore
  File "/home/iceman/.local/lib/python3.10/site-packages/discord/ext/commands/core.py", line 244, in wrapped
    raise CommandInvokeError(exc) from exc
discord.ext.commands.errors.CommandInvokeError: Command raised an exception: OperationalError: no such table: Users
2023-07-17 15:32:13,681 - discord.client - INFO - logging in using static token
2023-07-17 15:32:14,844 - discord.gateway - INFO - Shard ID None has connected to Gateway (Session ID: f97cfab6666355b97b232e196e7911f1).
2023-07-17 15:32:16,964 - root - INFO - Logged in as Anigay 2.0#7825
2023-07-17 15:32:20,908 - discord.ext.commands.bot - ERROR - Ignoring exception in command summon
Traceback (most recent call last):
  File "/home/iceman/.local/lib/python3.10/site-packages/discord/ext/commands/core.py", line 235, in wrapped
    ret = await coro(*args, **kwargs)
  File "/home/iceman/___/Anigay-2.0/src/Dev.py", line 41, in summon
    if ctx.author.id not in devids:
NameError: name 'devids' is not defined

The above exception was the direct cause of the following exception:

Traceback (most recent call last):
  File "/home/iceman/.local/lib/python3.10/site-packages/discord/ext/commands/bot.py", line 1350, in invoke
    await ctx.command.invoke(ctx)
  File "/home/iceman/.local/lib/python3.10/site-packages/discord/ext/commands/core.py", line 1029, in invoke
    await injected(*ctx.args, **ctx.kwargs)  # type: ignore
  File "/home/iceman/.local/lib/python3.10/site-packages/discord/ext/commands/core.py", line 244, in wrapped
    raise CommandInvokeError(exc) from exc
discord.ext.commands.errors.CommandInvokeError: Command raised an exception: NameError: name 'devids' is not defined
2023-07-17 15:32:58,244 - discord.client - INFO - logging in using static token
2023-07-17 15:32:59,508 - discord.gateway - INFO - Shard ID None has connected to Gateway (Session ID: f42cf3a6f759ee14b349d6fe805c6fde).
2023-07-17 15:33:01,669 - root - INFO - Logged in as Anigay 2.0#7825
2023-07-17 15:33:18,359 - asyncio - ERROR - Task was destroyed but it is pending!
task: <Task pending name='discord.py: on_message' coro=<Client._run_event() done, defined at /home/iceman/.local/lib/python3.10/site-packages/discord/client.py:433> wait_for=<Future pending cb=[Task.task_wakeup()]>>
2023-07-17 15:33:18,359 - discord.ext.commands.bot - ERROR - Ignoring exception in command select
Traceback (most recent call last):
  File "/home/iceman/.local/lib/python3.10/site-packages/discord/ext/commands/core.py", line 235, in wrapped
    ret = await coro(*args, **kwargs)
RuntimeError: coroutine ignored GeneratorExit

The above exception was the direct cause of the following exception:

Traceback (most recent call last):
  File "/home/iceman/.local/lib/python3.10/site-packages/discord/ext/commands/bot.py", line 1350, in invoke
    await ctx.command.invoke(ctx)
  File "/home/iceman/.local/lib/python3.10/site-packages/discord/ext/commands/core.py", line 1029, in invoke
    await injected(*ctx.args, **ctx.kwargs)  # type: ignore
  File "/home/iceman/.local/lib/python3.10/site-packages/discord/ext/commands/core.py", line 244, in wrapped
    raise CommandInvokeError(exc) from exc
discord.ext.commands.errors.CommandInvokeError: Command raised an exception: RuntimeError: coroutine ignored GeneratorExit
2023-07-17 15:34:47,218 - asyncio - ERROR - Task was destroyed but it is pending!
task: <Task pending name='discord.py: on_message' coro=<Client._run_event() done, defined at /home/iceman/.local/lib/python3.10/site-packages/discord/client.py:433> wait_for=<Future pending cb=[Task.task_wakeup()]>>
2023-07-17 15:34:47,219 - discord.ext.commands.bot - ERROR - Ignoring exception in command select
Traceback (most recent call last):
  File "/home/iceman/.local/lib/python3.10/site-packages/discord/ext/commands/core.py", line 235, in wrapped
    ret = await coro(*args, **kwargs)
RuntimeError: coroutine ignored GeneratorExit

The above exception was the direct cause of the following exception:

Traceback (most recent call last):
  File "/home/iceman/.local/lib/python3.10/site-packages/discord/ext/commands/bot.py", line 1350, in invoke
    await ctx.command.invoke(ctx)
  File "/home/iceman/.local/lib/python3.10/site-packages/discord/ext/commands/core.py", line 1029, in invoke
    await injected(*ctx.args, **ctx.kwargs)  # type: ignore
  File "/home/iceman/.local/lib/python3.10/site-packages/discord/ext/commands/core.py", line 244, in wrapped
    raise CommandInvokeError(exc) from exc
discord.ext.commands.errors.CommandInvokeError: Command raised an exception: RuntimeError: coroutine ignored GeneratorExit
2023-07-17 15:35:05,212 - asyncio - ERROR - Task was destroyed but it is pending!
task: <Task pending name='discord.py: on_message' coro=<Client._run_event() done, defined at /home/iceman/.local/lib/python3.10/site-packages/discord/client.py:433> wait_for=<Future pending cb=[Task.task_wakeup()]>>
2023-07-17 15:35:05,212 - discord.ext.commands.bot - ERROR - Ignoring exception in command select
Traceback (most recent call last):
  File "/home/iceman/.local/lib/python3.10/site-packages/discord/ext/commands/core.py", line 235, in wrapped
    ret = await coro(*args, **kwargs)
RuntimeError: coroutine ignored GeneratorExit

The above exception was the direct cause of the following exception:

Traceback (most recent call last):
  File "/home/iceman/.local/lib/python3.10/site-packages/discord/ext/commands/bot.py", line 1350, in invoke
    await ctx.command.invoke(ctx)
  File "/home/iceman/.local/lib/python3.10/site-packages/discord/ext/commands/core.py", line 1029, in invoke
    await injected(*ctx.args, **ctx.kwargs)  # type: ignore
  File "/home/iceman/.local/lib/python3.10/site-packages/discord/ext/commands/core.py", line 244, in wrapped
    raise CommandInvokeError(exc) from exc
discord.ext.commands.errors.CommandInvokeError: Command raised an exception: RuntimeError: coroutine ignored GeneratorExit
2023-07-17 15:35:17,146 - asyncio - ERROR - Task was destroyed but it is pending!
task: <Task pending name='discord.py: on_message' coro=<Client._run_event() done, defined at /home/iceman/.local/lib/python3.10/site-packages/discord/client.py:433> wait_for=<Future pending cb=[Task.task_wakeup()]>>
2023-07-17 15:35:17,147 - discord.ext.commands.bot - ERROR - Ignoring exception in command select
Traceback (most recent call last):
  File "/home/iceman/.local/lib/python3.10/site-packages/discord/ext/commands/core.py", line 235, in wrapped
    ret = await coro(*args, **kwargs)
RuntimeError: coroutine ignored GeneratorExit

The above exception was the direct cause of the following exception:

Traceback (most recent call last):
  File "/home/iceman/.local/lib/python3.10/site-packages/discord/ext/commands/bot.py", line 1350, in invoke
    await ctx.command.invoke(ctx)
  File "/home/iceman/.local/lib/python3.10/site-packages/discord/ext/commands/core.py", line 1029, in invoke
    await injected(*ctx.args, **ctx.kwargs)  # type: ignore
  File "/home/iceman/.local/lib/python3.10/site-packages/discord/ext/commands/core.py", line 244, in wrapped
    raise CommandInvokeError(exc) from exc
discord.ext.commands.errors.CommandInvokeError: Command raised an exception: RuntimeError: coroutine ignored GeneratorExit
2023-07-17 15:35:17,463 - discord.ext.commands.bot - ERROR - Ignoring exception in command inventory
Traceback (most recent call last):
  File "/home/iceman/.local/lib/python3.10/site-packages/discord/ext/commands/core.py", line 235, in wrapped
    ret = await coro(*args, **kwargs)
  File "/home/iceman/___/Anigay-2.0/src/User.py", line 165, in inventory
    await cursor.execute("SELECT * FROM Dex")
  File "/home/iceman/.local/lib/python3.10/site-packages/asqlite/__init__.py", line 210, in execute
    await self._post(self._cursor.execute, sql, parameters)
  File "/home/iceman/.local/lib/python3.10/site-packages/asqlite/__init__.py", line 85, in _call_entry
    result = entry.func(*entry.args, **entry.kwargs)
sqlite3.ProgrammingError: Cannot operate on a closed cursor.

The above exception was the direct cause of the following exception:

Traceback (most recent call last):
  File "/home/iceman/.local/lib/python3.10/site-packages/discord/ext/commands/bot.py", line 1350, in invoke
    await ctx.command.invoke(ctx)
  File "/home/iceman/.local/lib/python3.10/site-packages/discord/ext/commands/core.py", line 1029, in invoke
    await injected(*ctx.args, **ctx.kwargs)  # type: ignore
  File "/home/iceman/.local/lib/python3.10/site-packages/discord/ext/commands/core.py", line 244, in wrapped
    raise CommandInvokeError(exc) from exc
discord.ext.commands.errors.CommandInvokeError: Command raised an exception: ProgrammingError: Cannot operate on a closed cursor.
2023-07-17 15:35:37,786 - discord.client - INFO - logging in using static token
2023-07-17 15:35:38,945 - discord.gateway - INFO - Shard ID None has connected to Gateway (Session ID: 10947a0a2119c092f13c079af648ffd2).
2023-07-17 15:35:41,049 - root - INFO - Logged in as Anigay 2.0#7825
2023-07-17 15:35:42,818 - discord.ext.commands.bot - ERROR - Ignoring exception in command inventory
Traceback (most recent call last):
  File "/home/iceman/.local/lib/python3.10/site-packages/discord/ext/commands/core.py", line 235, in wrapped
    ret = await coro(*args, **kwargs)
  File "/home/iceman/___/Anigay-2.0/src/User.py", line 165, in inventory
    await cursor.execute("SELECT * FROM Dex")
  File "/home/iceman/.local/lib/python3.10/site-packages/asqlite/__init__.py", line 210, in execute
    await self._post(self._cursor.execute, sql, parameters)
  File "/home/iceman/.local/lib/python3.10/site-packages/asqlite/__init__.py", line 85, in _call_entry
    result = entry.func(*entry.args, **entry.kwargs)
sqlite3.ProgrammingError: Cannot operate on a closed cursor.

The above exception was the direct cause of the following exception:

Traceback (most recent call last):
  File "/home/iceman/.local/lib/python3.10/site-packages/discord/ext/commands/bot.py", line 1350, in invoke
    await ctx.command.invoke(ctx)
  File "/home/iceman/.local/lib/python3.10/site-packages/discord/ext/commands/core.py", line 1029, in invoke
    await injected(*ctx.args, **ctx.kwargs)  # type: ignore
  File "/home/iceman/.local/lib/python3.10/site-packages/discord/ext/commands/core.py", line 244, in wrapped
    raise CommandInvokeError(exc) from exc
discord.ext.commands.errors.CommandInvokeError: Command raised an exception: ProgrammingError: Cannot operate on a closed cursor.
2023-07-17 15:35:53,105 - asyncio - ERROR - Task was destroyed but it is pending!
task: <Task pending name='discord.py: on_message' coro=<Client._run_event() done, defined at /home/iceman/.local/lib/python3.10/site-packages/discord/client.py:433> wait_for=<Future pending cb=[Task.task_wakeup()]>>
2023-07-17 15:35:53,105 - discord.ext.commands.bot - ERROR - Ignoring exception in command select
Traceback (most recent call last):
  File "/home/iceman/.local/lib/python3.10/site-packages/discord/ext/commands/core.py", line 235, in wrapped
    ret = await coro(*args, **kwargs)
RuntimeError: coroutine ignored GeneratorExit

The above exception was the direct cause of the following exception:

Traceback (most recent call last):
  File "/home/iceman/.local/lib/python3.10/site-packages/discord/ext/commands/bot.py", line 1350, in invoke
    await ctx.command.invoke(ctx)
  File "/home/iceman/.local/lib/python3.10/site-packages/discord/ext/commands/core.py", line 1029, in invoke
    await injected(*ctx.args, **ctx.kwargs)  # type: ignore
  File "/home/iceman/.local/lib/python3.10/site-packages/discord/ext/commands/core.py", line 244, in wrapped
    raise CommandInvokeError(exc) from exc
discord.ext.commands.errors.CommandInvokeError: Command raised an exception: RuntimeError: coroutine ignored GeneratorExit
2023-07-17 16:09:35,651 - discord.client - INFO - logging in using static token
2023-07-17 16:09:36,773 - discord.gateway - INFO - Shard ID None has connected to Gateway (Session ID: d54af0c79ac3fd06131d19d8583a04dc).
2023-07-17 16:09:38,902 - root - INFO - Logged in as Anigay 2.0#7825
2023-07-17 16:11:03,075 - discord.client - INFO - logging in using static token
2023-07-17 16:11:04,115 - discord.gateway - INFO - Shard ID None has connected to Gateway (Session ID: 32290e91a68cf8550435b30a93ed235a).
2023-07-17 16:11:06,225 - root - INFO - Logged in as Anigay 2.0#7825
2023-07-17 16:11:07,309 - discord.ext.commands.bot - ERROR - Ignoring exception in command battle
Traceback (most recent call last):
  File "/home/iceman/.local/lib/python3.10/site-packages/discord/ext/commands/core.py", line 235, in wrapped
    ret = await coro(*args, **kwargs)
  File "/home/iceman/___/Anigay-2.0/src/Game.py", line 404, in battle
    enemy.ele_mult = calcEleAdvantage(oppo.element, user_card.element)
NameError: name 'enemy' is not defined

The above exception was the direct cause of the following exception:

Traceback (most recent call last):
  File "/home/iceman/.local/lib/python3.10/site-packages/discord/ext/commands/bot.py", line 1350, in invoke
    await ctx.command.invoke(ctx)
  File "/home/iceman/.local/lib/python3.10/site-packages/discord/ext/commands/core.py", line 1029, in invoke
    await injected(*ctx.args, **ctx.kwargs)  # type: ignore
  File "/home/iceman/.local/lib/python3.10/site-packages/discord/ext/commands/core.py", line 244, in wrapped
    raise CommandInvokeError(exc) from exc
discord.ext.commands.errors.CommandInvokeError: Command raised an exception: NameError: name 'enemy' is not defined
2023-07-17 16:11:15,440 - discord.client - INFO - logging in using static token
2023-07-17 16:11:16,334 - discord.gateway - INFO - Shard ID None has connected to Gateway (Session ID: adfb4a9617c304020c381a084ba0f10b).
2023-07-17 16:11:18,441 - root - INFO - Logged in as Anigay 2.0#7825
2023-07-17 16:33:29,154 - discord.gateway - INFO - Shard ID None has successfully RESUMED session adfb4a9617c304020c381a084ba0f10b.
2023-07-17 16:50:05,177 - discord.gateway - INFO - Shard ID None session has been invalidated.
2023-07-17 16:50:10,707 - discord.gateway - INFO - Shard ID None has connected to Gateway (Session ID: 84bab305632aa0bcfb47e019e7f3bd4e).
2023-07-17 16:50:12,913 - root - INFO - Logged in as Anigay 2.0#7825
2023-07-17 16:50:12,914 - discord.client - ERROR - Ignoring exception in on_ready
Traceback (most recent call last):
  File "/home/iceman/.local/lib/python3.10/site-packages/discord/client.py", line 441, in _run_event
    await coro(*args, **kwargs)
  File "/home/iceman/___/Anigay-2.0/src/Anigay.py", line 37, in on_ready
    await bot.add_cog(Debug(bot))
  File "/home/iceman/.local/lib/python3.10/site-packages/discord/ext/commands/bot.py", line 777, in add_cog
    raise discord.ClientException(f'Cog named {cog_name!r} already loaded')
discord.errors.ClientException: Cog named 'Debug' already loaded
2023-07-17 16:57:31,532 - discord.gateway - INFO - Shard ID None has successfully RESUMED session 84bab305632aa0bcfb47e019e7f3bd4e.
2023-07-17 17:08:07,521 - discord.client - INFO - logging in using static token
2023-07-17 17:08:08,731 - discord.gateway - INFO - Shard ID None has connected to Gateway (Session ID: 8158f2591d3e75658c764e4ddd254bc4).
2023-07-17 17:08:10,837 - root - INFO - Logged in as Anigay 2.0#7825
2023-07-17 17:08:47,595 - discord.client - INFO - logging in using static token
2023-07-17 17:08:48,769 - discord.gateway - INFO - Shard ID None has connected to Gateway (Session ID: ce34758838f64a159c9d0b666c64bb74).
2023-07-17 17:08:50,878 - root - INFO - Logged in as Anigay 2.0#7825
2023-07-17 17:09:38,225 - discord.client - INFO - logging in using static token
2023-07-17 17:09:39,492 - discord.gateway - INFO - Shard ID None has connected to Gateway (Session ID: 703fcd761aba6fe34e9ecbc7497abbc6).
2023-07-17 17:09:41,598 - root - INFO - Logged in as Anigay 2.0#7825
2023-07-17 17:16:05,203 - discord.client - INFO - logging in using static token
2023-07-17 17:16:06,532 - discord.gateway - INFO - Shard ID None has connected to Gateway (Session ID: 90fdf7c699a8b08a39f86b6e32e64221).
2023-07-17 17:16:08,736 - root - INFO - Logged in as Anigay 2.0#7825
2023-07-17 17:17:13,404 - discord.client - INFO - logging in using static token
2023-07-17 17:17:14,928 - discord.gateway - INFO - Shard ID None has connected to Gateway (Session ID: e4194fbd7e92afea5313c0e63b9ae7d3).
2023-07-17 17:17:17,090 - root - INFO - Logged in as Anigay 2.0#7825
2023-07-17 17:17:39,487 - discord.ext.commands.bot - ERROR - Ignoring exception in command inventory
Traceback (most recent call last):
  File "/home/iceman/.local/lib/python3.10/site-packages/discord/ext/commands/core.py", line 235, in wrapped
    ret = await coro(*args, **kwargs)
  File "/home/iceman/___/Anigay-2.0/src/User.py", line 165, in inventory
    await cursor.execute("SELECT * FROM Dex")
  File "/home/iceman/.local/lib/python3.10/site-packages/asqlite/__init__.py", line 210, in execute
    await self._post(self._cursor.execute, sql, parameters)
  File "/home/iceman/.local/lib/python3.10/site-packages/asqlite/__init__.py", line 85, in _call_entry
    result = entry.func(*entry.args, **entry.kwargs)
sqlite3.ProgrammingError: Cannot operate on a closed cursor.

The above exception was the direct cause of the following exception:

Traceback (most recent call last):
  File "/home/iceman/.local/lib/python3.10/site-packages/discord/ext/commands/bot.py", line 1350, in invoke
    await ctx.command.invoke(ctx)
  File "/home/iceman/.local/lib/python3.10/site-packages/discord/ext/commands/core.py", line 1029, in invoke
    await injected(*ctx.args, **ctx.kwargs)  # type: ignore
  File "/home/iceman/.local/lib/python3.10/site-packages/discord/ext/commands/core.py", line 244, in wrapped
    raise CommandInvokeError(exc) from exc
discord.ext.commands.errors.CommandInvokeError: Command raised an exception: ProgrammingError: Cannot operate on a closed cursor.
2023-07-17 17:17:45,667 - asyncio - ERROR - Task was destroyed but it is pending!
task: <Task pending name='discord.py: on_message' coro=<Client._run_event() done, defined at /home/iceman/.local/lib/python3.10/site-packages/discord/client.py:433> wait_for=<Future pending cb=[Task.task_wakeup()]>>
2023-07-17 17:17:45,668 - discord.ext.commands.bot - ERROR - Ignoring exception in command select
Traceback (most recent call last):
  File "/home/iceman/.local/lib/python3.10/site-packages/discord/ext/commands/core.py", line 235, in wrapped
    ret = await coro(*args, **kwargs)
RuntimeError: coroutine ignored GeneratorExit

The above exception was the direct cause of the following exception:

Traceback (most recent call last):
  File "/home/iceman/.local/lib/python3.10/site-packages/discord/ext/commands/bot.py", line 1350, in invoke
    await ctx.command.invoke(ctx)
  File "/home/iceman/.local/lib/python3.10/site-packages/discord/ext/commands/core.py", line 1029, in invoke
    await injected(*ctx.args, **ctx.kwargs)  # type: ignore
  File "/home/iceman/.local/lib/python3.10/site-packages/discord/ext/commands/core.py", line 244, in wrapped
    raise CommandInvokeError(exc) from exc
discord.ext.commands.errors.CommandInvokeError: Command raised an exception: RuntimeError: coroutine ignored GeneratorExit
2023-07-17 17:17:47,473 - discord.ext.commands.bot - ERROR - Ignoring exception in command battle
Traceback (most recent call last):
  File "/home/iceman/.local/lib/python3.10/site-packages/discord/ext/commands/core.py", line 235, in wrapped
    ret = await coro(*args, **kwargs)
  File "/home/iceman/___/Anigay-2.0/src/Game.py", line 444, in battle
    await battleRound( user_card, oppo, embed )
TypeError: Game.battle.<locals>.battleRound() takes 2 positional arguments but 3 were given

The above exception was the direct cause of the following exception:

Traceback (most recent call last):
  File "/home/iceman/.local/lib/python3.10/site-packages/discord/ext/commands/bot.py", line 1350, in invoke
    await ctx.command.invoke(ctx)
  File "/home/iceman/.local/lib/python3.10/site-packages/discord/ext/commands/core.py", line 1029, in invoke
    await injected(*ctx.args, **ctx.kwargs)  # type: ignore
  File "/home/iceman/.local/lib/python3.10/site-packages/discord/ext/commands/core.py", line 244, in wrapped
    raise CommandInvokeError(exc) from exc
discord.ext.commands.errors.CommandInvokeError: Command raised an exception: TypeError: Game.battle.<locals>.battleRound() takes 2 positional arguments but 3 were given
2023-07-17 17:18:05,242 - discord.client - INFO - logging in using static token
2023-07-17 17:18:06,528 - discord.gateway - INFO - Shard ID None has connected to Gateway (Session ID: 30f9fe7cebac064d2c0db815259ced70).
2023-07-17 17:18:08,184 - discord.ext.commands.bot - ERROR - Ignoring exception in command None
discord.ext.commands.errors.CommandNotFound: Command "bt" is not found
2023-07-17 17:18:08,701 - root - INFO - Logged in as Anigay 2.0#7825
2023-07-17 17:18:12,895 - discord.ext.commands.bot - ERROR - Ignoring exception in command battle
Traceback (most recent call last):
  File "/home/iceman/.local/lib/python3.10/site-packages/discord/ext/commands/core.py", line 235, in wrapped
    ret = await coro(*args, **kwargs)
  File "/home/iceman/___/Anigay-2.0/src/Game.py", line 444, in battle
    await battleRound( user_card, oppo, embed )
TypeError: Game.battle.<locals>.battleRound() takes 2 positional arguments but 3 were given

The above exception was the direct cause of the following exception:

Traceback (most recent call last):
  File "/home/iceman/.local/lib/python3.10/site-packages/discord/ext/commands/bot.py", line 1350, in invoke
    await ctx.command.invoke(ctx)
  File "/home/iceman/.local/lib/python3.10/site-packages/discord/ext/commands/core.py", line 1029, in invoke
    await injected(*ctx.args, **ctx.kwargs)  # type: ignore
  File "/home/iceman/.local/lib/python3.10/site-packages/discord/ext/commands/core.py", line 244, in wrapped
    raise CommandInvokeError(exc) from exc
discord.ext.commands.errors.CommandInvokeError: Command raised an exception: TypeError: Game.battle.<locals>.battleRound() takes 2 positional arguments but 3 were given
2023-07-17 17:18:27,088 - discord.client - INFO - logging in using static token
2023-07-17 17:18:28,460 - discord.gateway - INFO - Shard ID None has connected to Gateway (Session ID: d105c6fad6238fcbd89b0bc537d6cf26).
2023-07-17 17:18:30,637 - root - INFO - Logged in as Anigay 2.0#7825
2023-07-17 17:22:22,691 - discord.client - INFO - logging in using static token
2023-07-17 17:22:23,869 - discord.gateway - INFO - Shard ID None has connected to Gateway (Session ID: 8d4a0a6a498c820fb234e88f3596b5fa).
2023-07-17 17:22:25,421 - discord.ext.commands.bot - ERROR - Ignoring exception in command None
discord.ext.commands.errors.CommandNotFound: Command "bt" is not found
2023-07-17 17:22:26,061 - root - INFO - Logged in as Anigay 2.0#7825
2023-07-17 17:23:41,566 - discord.client - INFO - logging in using static token
2023-07-17 17:23:42,945 - discord.gateway - INFO - Shard ID None has connected to Gateway (Session ID: 8457ffec65507500ffe6234ecf33d40d).
2023-07-17 17:23:45,151 - root - INFO - Logged in as Anigay 2.0#7825
2023-07-17 17:41:48,084 - discord.gateway - INFO - Shard ID None has successfully RESUMED session 8457ffec65507500ffe6234ecf33d40d.
2023-07-17 18:24:26,098 - discord.gateway - INFO - Shard ID None session has been invalidated.
2023-07-17 18:24:31,658 - discord.gateway - INFO - Shard ID None has connected to Gateway (Session ID: 4dec786f86ebf7291b8671d000b5094a).
2023-07-17 18:24:33,826 - root - INFO - Logged in as Anigay 2.0#7825
2023-07-17 18:24:33,828 - discord.client - ERROR - Ignoring exception in on_ready
Traceback (most recent call last):
  File "/home/iceman/.local/lib/python3.10/site-packages/discord/client.py", line 441, in _run_event
    await coro(*args, **kwargs)
  File "/home/iceman/___/Anigay-2.0/src/Anigay.py", line 37, in on_ready
    await bot.add_cog(Debug(bot))
  File "/home/iceman/.local/lib/python3.10/site-packages/discord/ext/commands/bot.py", line 777, in add_cog
    raise discord.ClientException(f'Cog named {cog_name!r} already loaded')
discord.errors.ClientException: Cog named 'Debug' already loaded
2023-07-17 18:55:34,046 - discord.ext.commands.bot - ERROR - Ignoring exception in command summon
Traceback (most recent call last):
  File "/home/iceman/.local/lib/python3.10/site-packages/discord/ext/commands/core.py", line 235, in wrapped
    ret = await coro(*args, **kwargs)
  File "/home/iceman/___/Anigay-2.0/src/Dev.py", line 78, in summon
    card_index = card_data["dex"]
UnboundLocalError: local variable 'card_data' referenced before assignment

The above exception was the direct cause of the following exception:

Traceback (most recent call last):
  File "/home/iceman/.local/lib/python3.10/site-packages/discord/ext/commands/bot.py", line 1350, in invoke
    await ctx.command.invoke(ctx)
  File "/home/iceman/.local/lib/python3.10/site-packages/discord/ext/commands/core.py", line 1029, in invoke
    await injected(*ctx.args, **ctx.kwargs)  # type: ignore
  File "/home/iceman/.local/lib/python3.10/site-packages/discord/ext/commands/core.py", line 244, in wrapped
    raise CommandInvokeError(exc) from exc
discord.ext.commands.errors.CommandInvokeError: Command raised an exception: UnboundLocalError: local variable 'card_data' referenced before assignment
2023-07-17 18:56:10,296 - discord.ext.commands.bot - ERROR - Ignoring exception in command summon
Traceback (most recent call last):
  File "/home/iceman/.local/lib/python3.10/site-packages/discord/ext/commands/core.py", line 235, in wrapped
    ret = await coro(*args, **kwargs)
  File "/home/iceman/___/Anigay-2.0/src/Dev.py", line 78, in summon
    card_index = card_data["dex"]
UnboundLocalError: local variable 'card_data' referenced before assignment

The above exception was the direct cause of the following exception:

Traceback (most recent call last):
  File "/home/iceman/.local/lib/python3.10/site-packages/discord/ext/commands/bot.py", line 1350, in invoke
    await ctx.command.invoke(ctx)
  File "/home/iceman/.local/lib/python3.10/site-packages/discord/ext/commands/core.py", line 1029, in invoke
    await injected(*ctx.args, **ctx.kwargs)  # type: ignore
  File "/home/iceman/.local/lib/python3.10/site-packages/discord/ext/commands/core.py", line 244, in wrapped
    raise CommandInvokeError(exc) from exc
discord.ext.commands.errors.CommandInvokeError: Command raised an exception: UnboundLocalError: local variable 'card_data' referenced before assignment
2023-07-17 18:56:37,276 - discord.ext.commands.bot - ERROR - Ignoring exception in command inventory
Traceback (most recent call last):
  File "/home/iceman/.local/lib/python3.10/site-packages/discord/ext/commands/core.py", line 235, in wrapped
    ret = await coro(*args, **kwargs)
  File "/home/iceman/___/Anigay-2.0/src/User.py", line 165, in inventory
    await cursor.execute("SELECT * FROM Dex")
  File "/home/iceman/.local/lib/python3.10/site-packages/asqlite/__init__.py", line 210, in execute
    await self._post(self._cursor.execute, sql, parameters)
  File "/home/iceman/.local/lib/python3.10/site-packages/asqlite/__init__.py", line 85, in _call_entry
    result = entry.func(*entry.args, **entry.kwargs)
sqlite3.ProgrammingError: Cannot operate on a closed cursor.

The above exception was the direct cause of the following exception:

Traceback (most recent call last):
  File "/home/iceman/.local/lib/python3.10/site-packages/discord/ext/commands/bot.py", line 1350, in invoke
    await ctx.command.invoke(ctx)
  File "/home/iceman/.local/lib/python3.10/site-packages/discord/ext/commands/core.py", line 1029, in invoke
    await injected(*ctx.args, **ctx.kwargs)  # type: ignore
  File "/home/iceman/.local/lib/python3.10/site-packages/discord/ext/commands/core.py", line 244, in wrapped
    raise CommandInvokeError(exc) from exc
discord.ext.commands.errors.CommandInvokeError: Command raised an exception: ProgrammingError: Cannot operate on a closed cursor.
2023-07-17 19:25:15,126 - discord.gateway - INFO - Shard ID None has successfully RESUMED session 4dec786f86ebf7291b8671d000b5094a.
2023-07-17 19:44:45,358 - discord.gateway - INFO - Shard ID None has successfully RESUMED session 4dec786f86ebf7291b8671d000b5094a.
2023-07-17 20:39:35,284 - discord.gateway - INFO - Shard ID None session has been invalidated.
2023-07-17 20:39:41,200 - discord.gateway - INFO - Shard ID None has connected to Gateway (Session ID: e71f1d534d01a11d494690164c441c79).
2023-07-17 20:39:43,333 - root - INFO - Logged in as Anigay 2.0#7825
2023-07-17 20:39:43,335 - discord.client - ERROR - Ignoring exception in on_ready
Traceback (most recent call last):
  File "/home/iceman/.local/lib/python3.10/site-packages/discord/client.py", line 441, in _run_event
    await coro(*args, **kwargs)
  File "/home/iceman/___/Anigay-2.0/src/Anigay.py", line 37, in on_ready
    await bot.add_cog(Debug(bot))
  File "/home/iceman/.local/lib/python3.10/site-packages/discord/ext/commands/bot.py", line 777, in add_cog
    raise discord.ClientException(f'Cog named {cog_name!r} already loaded')
discord.errors.ClientException: Cog named 'Debug' already loaded
2023-07-17 20:44:55,349 - discord.gateway - INFO - Shard ID None has successfully RESUMED session e71f1d534d01a11d494690164c441c79.
2023-07-18 10:35:15,809 - discord.client - INFO - logging in using static token
2023-07-18 10:35:16,771 - discord.gateway - INFO - Shard ID None has connected to Gateway (Session ID: 540acfd1de4a0bdc72895dcb44810130).
2023-07-18 10:35:18,834 - root - INFO - Logged in as Anigay 2.0#7825
2023-07-18 10:35:26,646 - discord.ext.commands.bot - ERROR - Ignoring exception in command battle
Traceback (most recent call last):
  File "/home/iceman/.local/lib/python3.10/site-packages/discord/ext/commands/core.py", line 235, in wrapped
    ret = await coro(*args, **kwargs)
  File "/home/iceman/___/Anigay-2.0/src/Game.py", line 461, in battle
    await battleRound( oppo, user_card )
  File "/home/iceman/___/Anigay-2.0/src/Game.py", line 439, in battleRound
    fighter2.hp -= dmg
UnboundLocalError: local variable 'dmg' referenced before assignment

The above exception was the direct cause of the following exception:

Traceback (most recent call last):
  File "/home/iceman/.local/lib/python3.10/site-packages/discord/ext/commands/bot.py", line 1350, in invoke
    await ctx.command.invoke(ctx)
  File "/home/iceman/.local/lib/python3.10/site-packages/discord/ext/commands/core.py", line 1029, in invoke
    await injected(*ctx.args, **ctx.kwargs)  # type: ignore
  File "/home/iceman/.local/lib/python3.10/site-packages/discord/ext/commands/core.py", line 244, in wrapped
    raise CommandInvokeError(exc) from exc
discord.ext.commands.errors.CommandInvokeError: Command raised an exception: UnboundLocalError: local variable 'dmg' referenced before assignment
2023-07-18 10:36:48,609 - discord.client - INFO - logging in using static token
2023-07-18 10:36:49,874 - discord.gateway - INFO - Shard ID None has connected to Gateway (Session ID: 3b3bc0b62c1909350477dab7351627b3).
2023-07-18 10:36:51,941 - root - INFO - Logged in as Anigay 2.0#7825
2023-07-18 10:36:53,151 - discord.ext.commands.bot - ERROR - Ignoring exception in command None
discord.ext.commands.errors.CommandNotFound: Command "bt.bt" is not found
2023-07-18 10:36:56,292 - discord.ext.commands.bot - ERROR - Ignoring exception in command battle
Traceback (most recent call last):
  File "/home/iceman/.local/lib/python3.10/site-packages/discord/ext/commands/core.py", line 235, in wrapped
    ret = await coro(*args, **kwargs)
  File "/home/iceman/___/Anigay-2.0/src/Game.py", line 461, in battle
    await battleRound( user_card, oppo )
  File "/home/iceman/___/Anigay-2.0/src/Game.py", line 438, in battleRound
    dmg = int((((fighter1.current_atk*fighter1.atk*10)+638000)/(8.7 * fighter2.df*10)) * fighter1.ele_mult * CRITICAL_MULTIPLIER)
UnboundLocalError: local variable 'CRITICAL_MULTIPLIER' referenced before assignment

The above exception was the direct cause of the following exception:

Traceback (most recent call last):
  File "/home/iceman/.local/lib/python3.10/site-packages/discord/ext/commands/bot.py", line 1350, in invoke
    await ctx.command.invoke(ctx)
  File "/home/iceman/.local/lib/python3.10/site-packages/discord/ext/commands/core.py", line 1029, in invoke
    await injected(*ctx.args, **ctx.kwargs)  # type: ignore
  File "/home/iceman/.local/lib/python3.10/site-packages/discord/ext/commands/core.py", line 244, in wrapped
    raise CommandInvokeError(exc) from exc
discord.ext.commands.errors.CommandInvokeError: Command raised an exception: UnboundLocalError: local variable 'CRITICAL_MULTIPLIER' referenced before assignment
2023-07-18 10:37:54,011 - discord.client - INFO - logging in using static token
2023-07-18 10:37:54,861 - discord.gateway - INFO - Shard ID None has connected to Gateway (Session ID: 31c2c433438d439e4e219674fafb49db).
2023-07-18 10:37:56,913 - root - INFO - Logged in as Anigay 2.0#7825
2023-07-18 10:39:08,386 - discord.client - INFO - logging in using static token
2023-07-18 10:39:09,957 - discord.gateway - INFO - Shard ID None has connected to Gateway (Session ID: 27a2beef31b08490ad523fda503db273).
2023-07-18 10:39:10,470 - discord.ext.commands.bot - ERROR - Ignoring exception in command None
discord.ext.commands.errors.CommandNotFound: Command "bt" is not found
2023-07-18 10:39:12,273 - root - INFO - Logged in as Anigay 2.0#7825
2023-07-18 10:40:12,414 - discord.client - INFO - logging in using static token
2023-07-18 10:40:13,212 - discord.gateway - INFO - Shard ID None has connected to Gateway (Session ID: 4ba3aeaf833b9fae6635f338169a1542).
2023-07-18 10:40:15,279 - root - INFO - Logged in as Anigay 2.0#7825
2023-07-18 12:23:07,316 - discord.client - INFO - logging in using static token
2023-07-18 12:23:08,104 - discord.gateway - INFO - Shard ID None has connected to Gateway (Session ID: 9b930805bcfaa85d3ad51ff4e22a27b7).
2023-07-18 12:23:10,172 - root - INFO - Logged in as Anigay 2.0#7825
2023-07-18 13:15:20,395 - discord.gateway - INFO - Shard ID None session has been invalidated.
2023-07-18 13:15:25,847 - discord.gateway - INFO - Shard ID None has connected to Gateway (Session ID: 06b68b152a6fa33950de4fd78df8698e).
2023-07-18 13:15:27,940 - root - INFO - Logged in as Anigay 2.0#7825
2023-07-18 13:15:27,941 - discord.client - ERROR - Ignoring exception in on_ready
Traceback (most recent call last):
  File "/home/iceman/.local/lib/python3.10/site-packages/discord/client.py", line 441, in _run_event
    await coro(*args, **kwargs)
  File "/home/iceman/___/Anigay-2.0/src/Anigay.py", line 37, in on_ready
    await bot.add_cog(Debug(bot))
  File "/home/iceman/.local/lib/python3.10/site-packages/discord/ext/commands/bot.py", line 777, in add_cog
    raise discord.ClientException(f'Cog named {cog_name!r} already loaded')
discord.errors.ClientException: Cog named 'Debug' already loaded
2023-07-18 13:35:56,625 - discord.client - INFO - logging in using static token
2023-07-18 13:35:57,796 - discord.gateway - INFO - Shard ID None has connected to Gateway (Session ID: c1a725c447ec818de5a37cb27892eb49).
2023-07-18 13:35:59,868 - root - INFO - Logged in as Anigay 2.0#7825
2023-07-18 13:36:01,731 - discord.ext.commands.bot - ERROR - Ignoring exception in command battle
Traceback (most recent call last):
  File "/home/iceman/.local/lib/python3.10/site-packages/discord/ext/commands/core.py", line 235, in wrapped
    ret = await coro(*args, **kwargs)
  File "/home/iceman/___/Anigay-2.0/src/Game.py", line 468, in battle
    embed = displayHP(user_card, player_hp, oppo, enemy_hp, battle_round)
NameError: name 'player_hp' is not defined

The above exception was the direct cause of the following exception:

Traceback (most recent call last):
  File "/home/iceman/.local/lib/python3.10/site-packages/discord/ext/commands/bot.py", line 1350, in invoke
    await ctx.command.invoke(ctx)
  File "/home/iceman/.local/lib/python3.10/site-packages/discord/ext/commands/core.py", line 1029, in invoke
    await injected(*ctx.args, **ctx.kwargs)  # type: ignore
  File "/home/iceman/.local/lib/python3.10/site-packages/discord/ext/commands/core.py", line 244, in wrapped
    raise CommandInvokeError(exc) from exc
discord.ext.commands.errors.CommandInvokeError: Command raised an exception: NameError: name 'player_hp' is not defined
2023-07-18 13:36:34,467 - discord.client - INFO - logging in using static token
2023-07-18 13:36:35,582 - discord.gateway - INFO - Shard ID None has connected to Gateway (Session ID: 923361ce3e9c0cf69360e9750239717a).
2023-07-18 13:36:37,641 - root - INFO - Logged in as Anigay 2.0#7825
2023-07-18 13:37:13,893 - discord.client - INFO - logging in using static token
2023-07-18 13:37:15,007 - discord.gateway - INFO - Shard ID None has connected to Gateway (Session ID: f943c25d1d7b1e2d29fbbff1811e4276).
2023-07-18 13:37:17,076 - root - INFO - Logged in as Anigay 2.0#7825
2023-07-18 13:37:50,311 - discord.client - INFO - logging in using static token
2023-07-18 13:37:51,306 - discord.gateway - INFO - Shard ID None has connected to Gateway (Session ID: 869c44eb76fc2c284208636904d27fff).
2023-07-18 13:37:53,393 - root - INFO - Logged in as Anigay 2.0#7825
2023-07-18 13:38:27,664 - discord.client - INFO - logging in using static token
2023-07-18 13:38:28,624 - discord.gateway - INFO - Shard ID None has connected to Gateway (Session ID: d823d2666ccfefe0d6ed5a8075a85038).
2023-07-18 13:38:30,695 - root - INFO - Logged in as Anigay 2.0#7825
2023-07-18 13:39:15,875 - discord.client - INFO - logging in using static token
2023-07-18 13:39:16,785 - discord.gateway - INFO - Shard ID None has connected to Gateway (Session ID: c9ddd8ca2445b114559c1e74194a8542).
2023-07-18 13:39:18,863 - root - INFO - Logged in as Anigay 2.0#7825
2023-07-18 13:40:05,353 - discord.client - INFO - logging in using static token
2023-07-18 13:40:06,544 - discord.gateway - INFO - Shard ID None has connected to Gateway (Session ID: 3e492a96017d2f55e99929120f478b5d).
2023-07-18 13:40:08,616 - root - INFO - Logged in as Anigay 2.0#7825
2023-07-18 13:40:42,361 - discord.client - INFO - logging in using static token
2023-07-18 13:40:43,186 - discord.gateway - INFO - Shard ID None has connected to Gateway (Session ID: b31b3d939b1d386e72fab77ce89757b2).
2023-07-18 13:40:45,260 - root - INFO - Logged in as Anigay 2.0#7825
2023-07-18 13:40:57,087 - discord.client - INFO - logging in using static token
2023-07-18 13:40:58,037 - discord.gateway - INFO - Shard ID None has connected to Gateway (Session ID: 684ae45574ab4603ee15002f230d1428).
2023-07-18 13:41:00,129 - root - INFO - Logged in as Anigay 2.0#7825
2023-07-18 13:41:57,722 - discord.client - INFO - logging in using static token
2023-07-18 13:41:58,496 - discord.gateway - INFO - Shard ID None has connected to Gateway (Session ID: 8e53deefc8cc2591f4207ddd853094dc).
2023-07-18 13:42:00,572 - root - INFO - Logged in as Anigay 2.0#7825
2023-07-18 13:42:03,341 - discord.ext.commands.bot - ERROR - Ignoring exception in command battle
Traceback (most recent call last):
  File "/home/iceman/.local/lib/python3.10/site-packages/discord/ext/commands/core.py", line 235, in wrapped
    ret = await coro(*args, **kwargs)
  File "/home/iceman/___/Anigay-2.0/src/Game.py", line 518, in battle
    await battleRound( user_card, oppo )
  File "/home/iceman/___/Anigay-2.0/src/Game.py", line 484, in battleRound
    applyTalent( fighter1, fighter2, battle_round )
  File "/home/iceman/___/Anigay-2.0/src/Game.py", line 38, in applyTalent
    if fighter.rarity_s == "SR":
NameError: name 'fighter' is not defined

The above exception was the direct cause of the following exception:

Traceback (most recent call last):
  File "/home/iceman/.local/lib/python3.10/site-packages/discord/ext/commands/bot.py", line 1350, in invoke
    await ctx.command.invoke(ctx)
  File "/home/iceman/.local/lib/python3.10/site-packages/discord/ext/commands/core.py", line 1029, in invoke
    await injected(*ctx.args, **ctx.kwargs)  # type: ignore
  File "/home/iceman/.local/lib/python3.10/site-packages/discord/ext/commands/core.py", line 244, in wrapped
    raise CommandInvokeError(exc) from exc
discord.ext.commands.errors.CommandInvokeError: Command raised an exception: NameError: name 'fighter' is not defined
2023-07-18 13:42:27,364 - discord.client - INFO - logging in using static token
2023-07-18 13:42:28,354 - discord.gateway - INFO - Shard ID None has connected to Gateway (Session ID: e53ef35ed228a6211762feaf537fc212).
2023-07-18 13:42:30,416 - root - INFO - Logged in as Anigay 2.0#7825
2023-07-18 13:42:46,311 - discord.client - INFO - logging in using static token
2023-07-18 13:42:47,243 - discord.gateway - INFO - Shard ID None has connected to Gateway (Session ID: a9ef37dd427e2e44a2a1292753f01e6b).
2023-07-18 13:42:49,328 - root - INFO - Logged in as Anigay 2.0#7825
2023-07-18 13:43:54,276 - discord.client - INFO - logging in using static token
2023-07-18 13:43:55,227 - discord.gateway - INFO - Shard ID None has connected to Gateway (Session ID: 4f98c5a178ed5f2375409bc181647bc2).
2023-07-18 13:43:57,315 - root - INFO - Logged in as Anigay 2.0#7825
2023-07-18 13:47:12,607 - discord.client - INFO - logging in using static token
2023-07-18 13:47:13,514 - discord.gateway - INFO - Shard ID None has connected to Gateway (Session ID: b17ed331514dea6b4d4c1ad32c3fd6d2).
2023-07-18 13:47:15,588 - root - INFO - Logged in as Anigay 2.0#7825
2023-07-18 13:49:59,244 - discord.client - INFO - logging in using static token
2023-07-18 13:50:00,250 - discord.gateway - INFO - Shard ID None has connected to Gateway (Session ID: 8019e777229b6407dc727c43c6887f62).
2023-07-18 13:50:02,336 - root - INFO - Logged in as Anigay 2.0#7825
2023-07-18 13:50:08,120 - asyncio - ERROR - Exception in callback Future.set_result(None)
handle: <Handle Future.set_result(None)>
Traceback (most recent call last):
  File "/usr/lib/python3.10/asyncio/runners.py", line 44, in run
    return loop.run_until_complete(main)
  File "/usr/lib/python3.10/asyncio/base_events.py", line 633, in run_until_complete
    self.run_forever()
  File "/usr/lib/python3.10/asyncio/base_events.py", line 600, in run_forever
    self._run_once()
  File "/usr/lib/python3.10/asyncio/base_events.py", line 1860, in _run_once
    event_list = self._selector.select(timeout)
  File "/usr/lib/python3.10/selectors.py", line 469, in select
    fd_event_list = self._selector.poll(timeout, max_ev)
KeyboardInterrupt

During handling of the above exception, another exception occurred:

Traceback (most recent call last):
  File "/usr/lib/python3.10/asyncio/events.py", line 80, in _run
    self._context.run(self._callback, *self._args)
asyncio.exceptions.InvalidStateError: invalid state
2023-07-18 13:50:10,456 - discord.client - INFO - logging in using static token
2023-07-18 13:50:11,618 - discord.gateway - INFO - Shard ID None has connected to Gateway (Session ID: cebac769f87515dbcebb7b6757bac640).
2023-07-18 13:50:13,676 - root - INFO - Logged in as Anigay 2.0#7825
2023-07-18 13:56:06,010 - discord.client - INFO - logging in using static token
2023-07-18 13:56:07,052 - discord.gateway - INFO - Shard ID None has connected to Gateway (Session ID: fbb75ca5d5f5ade0037b6ad844805ca4).
2023-07-18 13:56:09,111 - root - INFO - Logged in as Anigay 2.0#7825
2023-07-18 13:57:07,517 - discord.client - INFO - logging in using static token
2023-07-18 13:57:09,618 - discord.gateway - INFO - Shard ID None has connected to Gateway (Session ID: a60c81d939125cb7ed4fed69ebe43e8f).
2023-07-18 13:57:12,242 - root - INFO - Logged in as Anigay 2.0#7825
2023-07-18 13:57:48,360 - discord.client - INFO - logging in using static token
2023-07-18 13:57:52,104 - discord.gateway - INFO - Shard ID None has connected to Gateway (Session ID: c6664004424776af240671beee35ab14).
2023-07-18 13:57:54,185 - root - INFO - Logged in as Anigay 2.0#7825
2023-07-18 13:59:28,560 - discord.client - INFO - logging in using static token
2023-07-18 13:59:31,025 - discord.gateway - INFO - Shard ID None has connected to Gateway (Session ID: 09dfe190584571d1ef27f34d7c5f8bbe).
2023-07-18 13:59:33,104 - root - INFO - Logged in as Anigay 2.0#7825
2023-07-18 14:04:41,534 - discord.client - INFO - logging in using static token
2023-07-18 14:04:42,846 - discord.gateway - INFO - Shard ID None has connected to Gateway (Session ID: c33f9c40d845b4d3ac0d9ea1cb54cfd9).
2023-07-18 14:04:44,923 - root - INFO - Logged in as Anigay 2.0#7825
2023-07-18 14:58:43,975 - discord.gateway - WARNING - Can't keep up, shard ID None websocket is 23.9s behind.
2023-07-18 15:35:12,248 - discord.gateway - INFO - Shard ID None has successfully RESUMED session c33f9c40d845b4d3ac0d9ea1cb54cfd9.
2023-07-18 15:44:17,388 - discord.gateway - INFO - Shard ID None has successfully RESUMED session c33f9c40d845b4d3ac0d9ea1cb54cfd9.
2023-07-18 16:22:23,514 - discord.client - INFO - logging in using static token
2023-07-18 16:22:24,928 - discord.gateway - INFO - Shard ID None has connected to Gateway (Session ID: 607d8b629ea1e00f728e52a864defa27).
2023-07-18 16:22:27,031 - root - INFO - Logged in as Anigay 2.0#7825
2023-07-18 16:22:32,828 - discord.ext.commands.bot - ERROR - Ignoring exception in command battle
Traceback (most recent call last):
  File "/home/iceman/.local/lib/python3.10/site-packages/discord/ext/commands/core.py", line 235, in wrapped
    ret = await coro(*args, **kwargs)
  File "/home/iceman/___/Anigay-2.0/src/Game.py", line 539, in battle
    await battleRound( user_card, oppo )
  File "/home/iceman/___/Anigay-2.0/src/Game.py", line 506, in battleRound
    mana_gained = int((15*(2-(fighter1.hp/fighter1.max_hp)))+(2*15/battle_round)*speed_multiplier)
ZeroDivisionError: division by zero

The above exception was the direct cause of the following exception:

Traceback (most recent call last):
  File "/home/iceman/.local/lib/python3.10/site-packages/discord/ext/commands/bot.py", line 1350, in invoke
    await ctx.command.invoke(ctx)
  File "/home/iceman/.local/lib/python3.10/site-packages/discord/ext/commands/core.py", line 1029, in invoke
    await injected(*ctx.args, **ctx.kwargs)  # type: ignore
  File "/home/iceman/.local/lib/python3.10/site-packages/discord/ext/commands/core.py", line 244, in wrapped
    raise CommandInvokeError(exc) from exc
discord.ext.commands.errors.CommandInvokeError: Command raised an exception: ZeroDivisionError: division by zero
2023-07-18 16:23:47,890 - discord.client - INFO - logging in using static token
2023-07-18 16:23:49,408 - discord.gateway - INFO - Shard ID None has connected to Gateway (Session ID: e80f5593ad6ffc21fa9b8b241dd8dc56).
2023-07-18 16:23:51,610 - root - INFO - Logged in as Anigay 2.0#7825
2023-07-18 16:24:02,121 - discord.ext.commands.bot - ERROR - Ignoring exception in command battle
Traceback (most recent call last):
  File "/home/iceman/.local/lib/python3.10/site-packages/discord/ext/commands/core.py", line 235, in wrapped
    ret = await coro(*args, **kwargs)
  File "/home/iceman/___/Anigay-2.0/src/Game.py", line 542, in battle
    await battleRound( oppo, user_card )
  File "/home/iceman/___/Anigay-2.0/src/Game.py", line 490, in battleRound
    if random.randint(1, 100) in range(1, fighter1.evasion+1):
AttributeError: 'FloorCard' object has no attribute 'evasion'

The above exception was the direct cause of the following exception:

Traceback (most recent call last):
  File "/home/iceman/.local/lib/python3.10/site-packages/discord/ext/commands/bot.py", line 1350, in invoke
    await ctx.command.invoke(ctx)
  File "/home/iceman/.local/lib/python3.10/site-packages/discord/ext/commands/core.py", line 1029, in invoke
    await injected(*ctx.args, **ctx.kwargs)  # type: ignore
  File "/home/iceman/.local/lib/python3.10/site-packages/discord/ext/commands/core.py", line 244, in wrapped
    raise CommandInvokeError(exc) from exc
discord.ext.commands.errors.CommandInvokeError: Command raised an exception: AttributeError: 'FloorCard' object has no attribute 'evasion'
2023-07-18 16:25:06,516 - discord.client - INFO - logging in using static token
2023-07-18 16:25:07,642 - discord.gateway - INFO - Shard ID None has connected to Gateway (Session ID: d8a1db602a81f561f8a9708ab3cb592a).
2023-07-18 16:25:09,744 - root - INFO - Logged in as Anigay 2.0#7825
2023-07-18 16:29:46,226 - discord.client - INFO - logging in using static token
2023-07-18 16:29:47,723 - discord.gateway - INFO - Shard ID None has connected to Gateway (Session ID: d913fb0af29742dfd459ae548759bc7e).
2023-07-18 16:29:49,835 - root - INFO - Logged in as Anigay 2.0#7825
2023-07-18 16:29:50,478 - discord.ext.commands.bot - ERROR - Ignoring exception in command battle
Traceback (most recent call last):
  File "/home/iceman/.local/lib/python3.10/site-packages/discord/ext/commands/core.py", line 235, in wrapped
    ret = await coro(*args, **kwargs)
  File "/home/iceman/___/Anigay-2.0/src/Game.py", line 491, in battle
    embed = displayHP(user_card, oppo, battle_round)
  File "/home/iceman/___/Anigay-2.0/src/Game.py", line 358, in displayHP
    player_mp_filled = round(player_mp_percentage / 100 * mp_bar_length)
NameError: name 'mp_bar_length' is not defined

The above exception was the direct cause of the following exception:

Traceback (most recent call last):
  File "/home/iceman/.local/lib/python3.10/site-packages/discord/ext/commands/bot.py", line 1350, in invoke
    await ctx.command.invoke(ctx)
  File "/home/iceman/.local/lib/python3.10/site-packages/discord/ext/commands/core.py", line 1029, in invoke
    await injected(*ctx.args, **ctx.kwargs)  # type: ignore
  File "/home/iceman/.local/lib/python3.10/site-packages/discord/ext/commands/core.py", line 244, in wrapped
    raise CommandInvokeError(exc) from exc
discord.ext.commands.errors.CommandInvokeError: Command raised an exception: NameError: name 'mp_bar_length' is not defined
2023-07-18 16:30:06,655 - discord.client - INFO - logging in using static token
2023-07-18 16:30:07,676 - discord.gateway - INFO - Shard ID None has connected to Gateway (Session ID: 4746d49bdeae8906ddf7abc5eccdd513).
2023-07-18 16:30:09,784 - root - INFO - Logged in as Anigay 2.0#7825
2023-07-18 16:30:10,957 - discord.ext.commands.bot - ERROR - Ignoring exception in command battle
Traceback (most recent call last):
  File "/home/iceman/.local/lib/python3.10/site-packages/discord/ext/commands/core.py", line 235, in wrapped
    ret = await coro(*args, **kwargs)
  File "/home/iceman/___/Anigay-2.0/src/Game.py", line 492, in battle
    embed = displayHP(user_card, oppo, battle_round)
  File "/home/iceman/___/Anigay-2.0/src/Game.py", line 365, in displayHP
    if player.mp > 100:
AttributeError: 'UserCard' object has no attribute 'mp'

The above exception was the direct cause of the following exception:

Traceback (most recent call last):
  File "/home/iceman/.local/lib/python3.10/site-packages/discord/ext/commands/bot.py", line 1350, in invoke
    await ctx.command.invoke(ctx)
  File "/home/iceman/.local/lib/python3.10/site-packages/discord/ext/commands/core.py", line 1029, in invoke
    await injected(*ctx.args, **ctx.kwargs)  # type: ignore
  File "/home/iceman/.local/lib/python3.10/site-packages/discord/ext/commands/core.py", line 244, in wrapped
    raise CommandInvokeError(exc) from exc
discord.ext.commands.errors.CommandInvokeError: Command raised an exception: AttributeError: 'UserCard' object has no attribute 'mp'
2023-07-18 16:30:28,436 - discord.client - INFO - logging in using static token
2023-07-18 16:30:29,439 - discord.gateway - INFO - Shard ID None has connected to Gateway (Session ID: d4b0a528ab0ce72db8adf0c814195df3).
2023-07-18 16:30:31,544 - root - INFO - Logged in as Anigay 2.0#7825
2023-07-18 16:31:36,051 - discord.client - INFO - logging in using static token
2023-07-18 16:31:37,276 - discord.gateway - INFO - Shard ID None has connected to Gateway (Session ID: 2fe6c7b38b56c11d06dac5399adb1f82).
2023-07-18 16:31:39,404 - root - INFO - Logged in as Anigay 2.0#7825
2023-07-18 16:33:23,787 - discord.client - INFO - logging in using static token
2023-07-18 16:33:24,855 - discord.gateway - INFO - Shard ID None has connected to Gateway (Session ID: 224d329a2eb7065a9e7c21c6afabb376).
2023-07-18 16:33:26,983 - root - INFO - Logged in as Anigay 2.0#7825
2023-07-18 16:33:39,556 - discord.ext.commands.bot - ERROR - Ignoring exception in command battle
Traceback (most recent call last):
  File "/home/iceman/.local/lib/python3.10/site-packages/discord/ext/commands/core.py", line 235, in wrapped
    ret = await coro(*args, **kwargs)
  File "/home/iceman/___/Anigay-2.0/src/Game.py", line 493, in battle
    embed = displayHP(user_card, oppo, battle_round)
  File "/home/iceman/___/Anigay-2.0/src/Game.py", line 365, in displayHP
    if player.mana > 100 or player_filled > 20:
UnboundLocalError: local variable 'player_filled' referenced before assignment

The above exception was the direct cause of the following exception:

Traceback (most recent call last):
  File "/home/iceman/.local/lib/python3.10/site-packages/discord/ext/commands/bot.py", line 1350, in invoke
    await ctx.command.invoke(ctx)
  File "/home/iceman/.local/lib/python3.10/site-packages/discord/ext/commands/core.py", line 1029, in invoke
    await injected(*ctx.args, **ctx.kwargs)  # type: ignore
  File "/home/iceman/.local/lib/python3.10/site-packages/discord/ext/commands/core.py", line 244, in wrapped
    raise CommandInvokeError(exc) from exc
discord.ext.commands.errors.CommandInvokeError: Command raised an exception: UnboundLocalError: local variable 'player_filled' referenced before assignment
2023-07-18 16:33:59,010 - discord.client - INFO - logging in using static token
2023-07-18 16:34:00,249 - discord.gateway - INFO - Shard ID None has connected to Gateway (Session ID: 1d2e9238c90df9a5e12fabf212667022).
2023-07-18 16:34:02,345 - root - INFO - Logged in as Anigay 2.0#7825
2023-07-18 16:34:41,177 - discord.client - INFO - logging in using static token
2023-07-18 16:34:42,250 - discord.gateway - INFO - Shard ID None has connected to Gateway (Session ID: 473729474dfd5c1da60da1bcd5902da3).
2023-07-18 16:34:44,367 - root - INFO - Logged in as Anigay 2.0#7825
2023-07-18 16:36:21,950 - discord.ext.commands.bot - ERROR - Ignoring exception in command None
discord.ext.commands.errors.CommandNotFound: Command "cl" is not found
2023-07-18 16:37:42,558 - discord.client - INFO - logging in using static token
2023-07-18 16:37:43,660 - discord.gateway - INFO - Shard ID None has connected to Gateway (Session ID: e79a9840d95fa45446677a051cc1e393).
2023-07-18 16:37:45,796 - root - INFO - Logged in as Anigay 2.0#7825
2023-07-18 16:37:49,920 - discord.ext.commands.bot - ERROR - Ignoring exception in command battle
Traceback (most recent call last):
  File "/home/iceman/.local/lib/python3.10/site-packages/discord/ext/commands/core.py", line 235, in wrapped
    ret = await coro(*args, **kwargs)
  File "/home/iceman/___/Anigay-2.0/src/Game.py", line 493, in battle
    embed = displayHP(user_card, oppo, battle_round)
  File "/home/iceman/___/Anigay-2.0/src/Game.py", line 357, in displayHP
    player_mp_percentage = player.mana / player.max_mana
ZeroDivisionError: division by zero

The above exception was the direct cause of the following exception:

Traceback (most recent call last):
  File "/home/iceman/.local/lib/python3.10/site-packages/discord/ext/commands/bot.py", line 1350, in invoke
    await ctx.command.invoke(ctx)
  File "/home/iceman/.local/lib/python3.10/site-packages/discord/ext/commands/core.py", line 1029, in invoke
    await injected(*ctx.args, **ctx.kwargs)  # type: ignore
  File "/home/iceman/.local/lib/python3.10/site-packages/discord/ext/commands/core.py", line 244, in wrapped
    raise CommandInvokeError(exc) from exc
discord.ext.commands.errors.CommandInvokeError: Command raised an exception: ZeroDivisionError: division by zero
2023-07-18 16:38:56,229 - discord.client - INFO - logging in using static token
2023-07-18 16:38:57,325 - discord.gateway - INFO - Shard ID None has connected to Gateway (Session ID: 5b1d082567120943ef91202eca963556).
2023-07-18 16:38:59,433 - root - INFO - Logged in as Anigay 2.0#7825
2023-07-18 16:41:44,220 - discord.client - INFO - logging in using static token
2023-07-18 16:41:45,137 - discord.gateway - INFO - Shard ID None has connected to Gateway (Session ID: c871f6ce0cee8ffe70b11fadfa19358d).
2023-07-18 16:41:47,290 - root - INFO - Logged in as Anigay 2.0#7825
2023-07-18 16:43:46,742 - discord.client - INFO - logging in using static token
2023-07-18 16:43:47,800 - discord.gateway - INFO - Shard ID None has connected to Gateway (Session ID: 2029ca86cb95002e2e0456b463d9ad97).
2023-07-18 16:43:49,897 - root - INFO - Logged in as Anigay 2.0#7825
2023-07-18 16:45:40,415 - discord.client - INFO - logging in using static token
2023-07-18 16:45:41,465 - discord.gateway - INFO - Shard ID None has connected to Gateway (Session ID: 82de27ddf68173a3ef94eb539d8e60cd).
2023-07-18 16:45:42,797 - discord.ext.commands.bot - ERROR - Ignoring exception in command None
discord.ext.commands.errors.CommandNotFound: Command "bt" is not found
2023-07-18 16:45:43,564 - root - INFO - Logged in as Anigay 2.0#7825
2023-07-18 16:46:54,520 - discord.client - INFO - logging in using static token
2023-07-18 16:46:55,808 - discord.gateway - INFO - Shard ID None has connected to Gateway (Session ID: bb51dc2f2b64e44c4db2c2e190c5ecd1).
2023-07-18 16:46:56,833 - discord.ext.commands.bot - ERROR - Ignoring exception in command None
discord.ext.commands.errors.CommandNotFound: Command "bt" is not found
2023-07-18 16:46:57,936 - root - INFO - Logged in as Anigay 2.0#7825
2023-07-18 16:55:53,003 - discord.client - INFO - logging in using static token
2023-07-18 16:55:54,147 - discord.gateway - INFO - Shard ID None has connected to Gateway (Session ID: 6e803403edc9e7a0dd29e15c65199afc).
2023-07-18 16:55:56,321 - root - INFO - Logged in as Anigay 2.0#7825
2023-07-18 16:57:44,120 - discord.client - INFO - logging in using static token
2023-07-18 16:57:45,130 - discord.gateway - INFO - Shard ID None has connected to Gateway (Session ID: b2f92b841d8a398b8b6d83cf16244fd3).
2023-07-18 16:57:47,284 - root - INFO - Logged in as Anigay 2.0#7825
2023-07-18 16:58:07,298 - discord.client - INFO - logging in using static token
2023-07-18 16:58:08,478 - discord.gateway - INFO - Shard ID None has connected to Gateway (Session ID: 102645621fad059351be015c57968cee).
2023-07-18 16:58:10,623 - root - INFO - Logged in as Anigay 2.0#7825
2023-07-18 16:59:06,135 - discord.client - INFO - logging in using static token
2023-07-18 16:59:07,055 - discord.gateway - INFO - Shard ID None has connected to Gateway (Session ID: 98c1656ca2af6bcafc4dec4440f8bcea).
2023-07-18 16:59:09,191 - root - INFO - Logged in as Anigay 2.0#7825
2023-07-18 17:00:22,319 - discord.client - INFO - logging in using static token
2023-07-18 17:00:23,667 - discord.gateway - INFO - Shard ID None has connected to Gateway (Session ID: 1c9fe3ffbb989ba69b8968f71554bfd1).
2023-07-18 17:00:25,772 - root - INFO - Logged in as Anigay 2.0#7825
2023-07-18 17:00:49,482 - discord.client - INFO - logging in using static token
2023-07-18 17:00:50,680 - discord.gateway - INFO - Shard ID None has connected to Gateway (Session ID: 89831d5a71882198935ff001cda3762b).
2023-07-18 17:00:52,796 - root - INFO - Logged in as Anigay 2.0#7825
2023-07-18 17:01:18,112 - discord.client - INFO - logging in using static token
2023-07-18 17:01:19,091 - discord.gateway - INFO - Shard ID None has connected to Gateway (Session ID: 06bcb7bc4420836d5fed06de46d3f3b9).
2023-07-18 17:01:21,211 - root - INFO - Logged in as Anigay 2.0#7825
2023-07-18 17:05:03,564 - discord.client - INFO - logging in using static token
2023-07-18 17:05:04,538 - discord.gateway - INFO - Shard ID None has connected to Gateway (Session ID: cf23220b0be3d596b80b81af4fb09f24).
2023-07-18 17:05:06,644 - root - INFO - Logged in as Anigay 2.0#7825
2023-07-18 17:05:17,085 - discord.ext.commands.bot - ERROR - Ignoring exception in command battle
Traceback (most recent call last):
  File "/home/iceman/.local/lib/python3.10/site-packages/discord/ext/commands/core.py", line 235, in wrapped
    ret = await coro(*args, **kwargs)
  File "/home/iceman/___/Anigay-2.0/src/Game.py", line 600, in battle
    await battleRound( user_card, oppo )
  File "/home/iceman/___/Anigay-2.0/src/Game.py", line 540, in battleRound
    applyTalent( fighter1, fighter2, battle_round )
  File "/home/iceman/___/Anigay-2.0/src/Game.py", line 50, in applyTalent
    fighter1.max_hp -= bonus
UnboundLocalError: local variable 'bonus' referenced before assignment

The above exception was the direct cause of the following exception:

Traceback (most recent call last):
  File "/home/iceman/.local/lib/python3.10/site-packages/discord/ext/commands/bot.py", line 1350, in invoke
    await ctx.command.invoke(ctx)
  File "/home/iceman/.local/lib/python3.10/site-packages/discord/ext/commands/core.py", line 1029, in invoke
    await injected(*ctx.args, **ctx.kwargs)  # type: ignore
  File "/home/iceman/.local/lib/python3.10/site-packages/discord/ext/commands/core.py", line 244, in wrapped
    raise CommandInvokeError(exc) from exc
discord.ext.commands.errors.CommandInvokeError: Command raised an exception: UnboundLocalError: local variable 'bonus' referenced before assignment
2023-07-18 17:06:10,787 - discord.client - INFO - logging in using static token
2023-07-18 17:06:11,741 - discord.gateway - INFO - Shard ID None has connected to Gateway (Session ID: f824deddec8548398b64f2c638864ea8).
2023-07-18 17:06:13,888 - root - INFO - Logged in as Anigay 2.0#7825
2023-07-18 17:16:59,723 - discord.client - INFO - logging in using static token
2023-07-18 17:17:00,919 - discord.gateway - INFO - Shard ID None has connected to Gateway (Session ID: 462eb0ed3c65deb86d537c10b36d7e4e).
2023-07-18 17:17:03,037 - root - INFO - Logged in as Anigay 2.0#7825
2023-07-18 17:18:08,142 - discord.client - INFO - logging in using static token
2023-07-18 17:18:09,327 - discord.gateway - INFO - Shard ID None has connected to Gateway (Session ID: cd25c97cb1e1b65ad28dad1313162264).
2023-07-18 17:18:11,376 - discord.ext.commands.bot - ERROR - Ignoring exception in command None
discord.ext.commands.errors.CommandNotFound: Command "bt" is not found
2023-07-18 17:18:11,542 - root - INFO - Logged in as Anigay 2.0#7825
2023-07-18 17:48:51,366 - discord.gateway - INFO - Shard ID None has successfully RESUMED session cd25c97cb1e1b65ad28dad1313162264.
2023-07-18 17:50:47,252 - discord.ext.commands.bot - ERROR - Ignoring exception in command inventory
Traceback (most recent call last):
  File "/home/iceman/.local/lib/python3.10/site-packages/discord/ext/commands/core.py", line 235, in wrapped
    ret = await coro(*args, **kwargs)
  File "/home/iceman/___/Anigay-2.0/src/User.py", line 165, in inventory
    await cursor.execute("SELECT * FROM Dex")
  File "/home/iceman/.local/lib/python3.10/site-packages/asqlite/__init__.py", line 210, in execute
    await self._post(self._cursor.execute, sql, parameters)
  File "/home/iceman/.local/lib/python3.10/site-packages/asqlite/__init__.py", line 85, in _call_entry
    result = entry.func(*entry.args, **entry.kwargs)
sqlite3.ProgrammingError: Cannot operate on a closed cursor.

The above exception was the direct cause of the following exception:

Traceback (most recent call last):
  File "/home/iceman/.local/lib/python3.10/site-packages/discord/ext/commands/bot.py", line 1350, in invoke
    await ctx.command.invoke(ctx)
  File "/home/iceman/.local/lib/python3.10/site-packages/discord/ext/commands/core.py", line 1029, in invoke
    await injected(*ctx.args, **ctx.kwargs)  # type: ignore
  File "/home/iceman/.local/lib/python3.10/site-packages/discord/ext/commands/core.py", line 244, in wrapped
    raise CommandInvokeError(exc) from exc
discord.ext.commands.errors.CommandInvokeError: Command raised an exception: ProgrammingError: Cannot operate on a closed cursor.
2023-07-18 17:50:51,439 - discord.ext.commands.bot - ERROR - Ignoring exception in command select
Traceback (most recent call last):
  File "/home/iceman/.local/lib/python3.10/site-packages/discord/ext/commands/core.py", line 235, in wrapped
    ret = await coro(*args, **kwargs)
  File "/home/iceman/___/Anigay-2.0/src/User.py", line 208, in select
    await connection.commit()
  File "/home/iceman/.local/lib/python3.10/site-packages/asqlite/__init__.py", line 381, in commit
    return await self._post(self._conn.commit)
  File "/home/iceman/.local/lib/python3.10/site-packages/asqlite/__init__.py", line 85, in _call_entry
    result = entry.func(*entry.args, **entry.kwargs)
sqlite3.ProgrammingError: Cannot operate on a closed database.

The above exception was the direct cause of the following exception:

Traceback (most recent call last):
  File "/home/iceman/.local/lib/python3.10/site-packages/discord/ext/commands/bot.py", line 1350, in invoke
    await ctx.command.invoke(ctx)
  File "/home/iceman/.local/lib/python3.10/site-packages/discord/ext/commands/core.py", line 1029, in invoke
    await injected(*ctx.args, **ctx.kwargs)  # type: ignore
  File "/home/iceman/.local/lib/python3.10/site-packages/discord/ext/commands/core.py", line 244, in wrapped
    raise CommandInvokeError(exc) from exc
discord.ext.commands.errors.CommandInvokeError: Command raised an exception: ProgrammingError: Cannot operate on a closed database.
2023-07-18 17:57:11,124 - discord.ext.commands.bot - ERROR - Ignoring exception in command None
discord.ext.commands.errors.CommandNotFound: Command "rd" is not found
2023-07-18 18:03:14,313 - discord.client - INFO - logging in using static token
2023-07-18 18:03:15,464 - discord.gateway - INFO - Shard ID None has connected to Gateway (Session ID: cc6f05779e4be3c2ac9909aa0d3326dd).
2023-07-18 18:03:17,581 - root - INFO - Logged in as Anigay 2.0#7825
2023-07-18 18:03:23,164 - discord.ext.commands.bot - ERROR - Ignoring exception in command battle
Traceback (most recent call last):
  File "/home/iceman/.local/lib/python3.10/site-packages/discord/ext/commands/core.py", line 235, in wrapped
    ret = await coro(*args, **kwargs)
  File "/home/iceman/___/Anigay-2.0/src/Game.py", line 638, in battle
    await battleRound( user_card, oppo )
  File "/home/iceman/___/Anigay-2.0/src/Game.py", line 573, in battleRound
    talent_message = applyTalent( fighter1, fighter2, battle_round )
  File "/home/iceman/___/Anigay-2.0/src/Game.py", line 67, in applyTalent
    if figher1.mana == 100:
NameError: name 'figher1' is not defined

The above exception was the direct cause of the following exception:

Traceback (most recent call last):
  File "/home/iceman/.local/lib/python3.10/site-packages/discord/ext/commands/bot.py", line 1350, in invoke
    await ctx.command.invoke(ctx)
  File "/home/iceman/.local/lib/python3.10/site-packages/discord/ext/commands/core.py", line 1029, in invoke
    await injected(*ctx.args, **ctx.kwargs)  # type: ignore
  File "/home/iceman/.local/lib/python3.10/site-packages/discord/ext/commands/core.py", line 244, in wrapped
    raise CommandInvokeError(exc) from exc
discord.ext.commands.errors.CommandInvokeError: Command raised an exception: NameError: name 'figher1' is not defined
2023-07-18 18:03:33,340 - discord.client - INFO - logging in using static token
2023-07-18 18:03:34,510 - discord.gateway - INFO - Shard ID None has connected to Gateway (Session ID: e3cecf4e3d9f97edf95e21eb9f56dfff).
2023-07-18 18:03:36,559 - discord.ext.commands.bot - ERROR - Ignoring exception in command None
discord.ext.commands.errors.CommandNotFound: Command "bt" is not found
2023-07-18 18:03:36,608 - root - INFO - Logged in as Anigay 2.0#7825
2023-07-18 18:03:50,359 - discord.ext.commands.bot - ERROR - Ignoring exception in command battle
Traceback (most recent call last):
  File "/home/iceman/.local/lib/python3.10/site-packages/discord/ext/commands/core.py", line 235, in wrapped
    ret = await coro(*args, **kwargs)
  File "/home/iceman/___/Anigay-2.0/src/Game.py", line 638, in battle
    await battleRound( user_card, oppo )
  File "/home/iceman/___/Anigay-2.0/src/Game.py", line 573, in battleRound
    talent_message = applyTalent( fighter1, fighter2, battle_round )
  File "/home/iceman/___/Anigay-2.0/src/Game.py", line 75, in applyTalent
    if figher.name == "Giyu Tomioka":
NameError: name 'figher' is not defined

The above exception was the direct cause of the following exception:

Traceback (most recent call last):
  File "/home/iceman/.local/lib/python3.10/site-packages/discord/ext/commands/bot.py", line 1350, in invoke
    await ctx.command.invoke(ctx)
  File "/home/iceman/.local/lib/python3.10/site-packages/discord/ext/commands/core.py", line 1029, in invoke
    await injected(*ctx.args, **ctx.kwargs)  # type: ignore
  File "/home/iceman/.local/lib/python3.10/site-packages/discord/ext/commands/core.py", line 244, in wrapped
    raise CommandInvokeError(exc) from exc
discord.ext.commands.errors.CommandInvokeError: Command raised an exception: NameError: name 'figher' is not defined
2023-07-18 18:04:30,161 - discord.client - INFO - logging in using static token
2023-07-18 18:04:31,262 - discord.gateway - INFO - Shard ID None has connected to Gateway (Session ID: f13e212bac94f4a9df791bd2166fa887).
2023-07-18 18:04:33,400 - root - INFO - Logged in as Anigay 2.0#7825
2023-07-18 18:04:43,805 - discord.ext.commands.bot - ERROR - Ignoring exception in command battle
Traceback (most recent call last):
  File "/home/iceman/.local/lib/python3.10/site-packages/discord/ext/commands/core.py", line 235, in wrapped
    ret = await coro(*args, **kwargs)
  File "/home/iceman/___/Anigay-2.0/src/Game.py", line 638, in battle
    await battleRound( user_card, oppo )
  File "/home/iceman/___/Anigay-2.0/src/Game.py", line 573, in battleRound
    talent_message = applyTalent( fighter1, fighter2, battle_round )
  File "/home/iceman/___/Anigay-2.0/src/Game.py", line 75, in applyTalent
    if fighter.name == "Giyu Tomioka":
NameError: name 'fighter' is not defined

The above exception was the direct cause of the following exception:

Traceback (most recent call last):
  File "/home/iceman/.local/lib/python3.10/site-packages/discord/ext/commands/bot.py", line 1350, in invoke
    await ctx.command.invoke(ctx)
  File "/home/iceman/.local/lib/python3.10/site-packages/discord/ext/commands/core.py", line 1029, in invoke
    await injected(*ctx.args, **ctx.kwargs)  # type: ignore
  File "/home/iceman/.local/lib/python3.10/site-packages/discord/ext/commands/core.py", line 244, in wrapped
    raise CommandInvokeError(exc) from exc
discord.ext.commands.errors.CommandInvokeError: Command raised an exception: NameError: name 'fighter' is not defined
2023-07-18 18:05:13,974 - discord.client - INFO - logging in using static token
2023-07-18 18:05:15,581 - discord.gateway - INFO - Shard ID None has connected to Gateway (Session ID: 5670f18c70f8a958da526ef3c639031a).
2023-07-18 18:05:17,672 - discord.ext.commands.bot - ERROR - Ignoring exception in command None
discord.ext.commands.errors.CommandNotFound: Command "bt" is not found
2023-07-18 18:05:17,757 - root - INFO - Logged in as Anigay 2.0#7825
2023-07-18 18:05:31,528 - discord.ext.commands.bot - ERROR - Ignoring exception in command battle
Traceback (most recent call last):
  File "/home/iceman/.local/lib/python3.10/site-packages/discord/ext/commands/core.py", line 235, in wrapped
    ret = await coro(*args, **kwargs)
  File "/home/iceman/___/Anigay-2.0/src/Game.py", line 638, in battle
    await battleRound( user_card, oppo )
  File "/home/iceman/___/Anigay-2.0/src/Game.py", line 573, in battleRound
    talent_message = applyTalent( fighter1, fighter2, battle_round )
  File "/home/iceman/___/Anigay-2.0/src/Game.py", line 78, in applyTalent
    ele_mult = calcEleAdvantage(fighter1, fighter2)
  File "/home/iceman/___/Anigay-2.0/src/Game.py", line 60, in calcEleAdvantage
    return elements[element1][element2]
KeyError: <CardClass.UserCard object at 0x7f4fc030b6d0>

The above exception was the direct cause of the following exception:

Traceback (most recent call last):
  File "/home/iceman/.local/lib/python3.10/site-packages/discord/ext/commands/bot.py", line 1350, in invoke
    await ctx.command.invoke(ctx)
  File "/home/iceman/.local/lib/python3.10/site-packages/discord/ext/commands/core.py", line 1029, in invoke
    await injected(*ctx.args, **ctx.kwargs)  # type: ignore
  File "/home/iceman/.local/lib/python3.10/site-packages/discord/ext/commands/core.py", line 244, in wrapped
    raise CommandInvokeError(exc) from exc
discord.ext.commands.errors.CommandInvokeError: Command raised an exception: KeyError: <CardClass.UserCard object at 0x7f4fc030b6d0>
2023-07-18 18:05:49,783 - discord.client - INFO - logging in using static token
2023-07-18 18:05:50,717 - discord.gateway - INFO - Shard ID None has connected to Gateway (Session ID: 178a3928bed48d0438cfbf8ae7b461b5).
2023-07-18 18:05:52,856 - root - INFO - Logged in as Anigay 2.0#7825
2023-07-18 18:07:51,492 - discord.client - INFO - logging in using static token
2023-07-18 18:07:52,629 - discord.gateway - INFO - Shard ID None has connected to Gateway (Session ID: 909cc8cd604cb222de9a0c6a457a7321).
2023-07-18 18:07:53,363 - discord.ext.commands.bot - ERROR - Ignoring exception in command None
discord.ext.commands.errors.CommandNotFound: Command "bt" is not found
2023-07-18 18:07:54,732 - root - INFO - Logged in as Anigay 2.0#7825
2023-07-18 18:08:57,870 - discord.client - INFO - logging in using static token
2023-07-18 18:08:58,675 - discord.gateway - INFO - Shard ID None has connected to Gateway (Session ID: 8f4927a997217ebde32283f58181c3ca).
2023-07-18 18:09:00,785 - root - INFO - Logged in as Anigay 2.0#7825
2023-07-18 18:09:45,798 - discord.client - INFO - logging in using static token
2023-07-18 18:09:46,966 - discord.gateway - INFO - Shard ID None has connected to Gateway (Session ID: cafe1ea3ddc3b50dafbd9c83e5d882f5).
2023-07-18 18:09:49,071 - root - INFO - Logged in as Anigay 2.0#7825
2023-07-18 18:10:41,943 - discord.client - INFO - logging in using static token
2023-07-18 18:10:43,652 - discord.gateway - INFO - Shard ID None has connected to Gateway (Session ID: 527e6ff651e7f74bf1d0e51f4c40180b).
2023-07-18 18:10:45,719 - discord.ext.commands.bot - ERROR - Ignoring exception in command None
discord.ext.commands.errors.CommandNotFound: Command "bt" is not found
2023-07-18 18:10:45,780 - root - INFO - Logged in as Anigay 2.0#7825
2023-07-18 18:11:51,716 - discord.client - INFO - logging in using static token
2023-07-18 18:11:53,507 - discord.gateway - INFO - Shard ID None has connected to Gateway (Session ID: a1b332c23452e39f719748abb429fd0f).
2023-07-18 18:11:55,760 - root - INFO - Logged in as Anigay 2.0#7825
2023-07-18 18:12:32,027 - discord.client - INFO - logging in using static token
2023-07-18 18:12:33,182 - discord.gateway - INFO - Shard ID None has connected to Gateway (Session ID: 3b693b23de4bba7872efd720cbb01226).
2023-07-18 18:12:35,396 - root - INFO - Logged in as Anigay 2.0#7825
2023-07-18 18:13:08,172 - discord.client - INFO - logging in using static token
2023-07-18 18:13:09,591 - discord.gateway - INFO - Shard ID None has connected to Gateway (Session ID: 18fa4b380977df55295257e83af0af72).
2023-07-18 18:13:11,828 - root - INFO - Logged in as Anigay 2.0#7825
2023-07-18 18:14:03,183 - discord.client - INFO - logging in using static token
2023-07-18 18:14:04,381 - discord.gateway - INFO - Shard ID None has connected to Gateway (Session ID: d7bb509d3a9238887ab552befabf9396).
2023-07-18 18:14:06,550 - root - INFO - Logged in as Anigay 2.0#7825
2023-07-18 18:14:41,710 - discord.client - INFO - logging in using static token
2023-07-18 18:14:43,066 - discord.gateway - INFO - Shard ID None has connected to Gateway (Session ID: db56aad3885d8783a1e9478bbb0ba9c6).
2023-07-18 18:14:45,310 - root - INFO - Logged in as Anigay 2.0#7825
2023-07-18 18:15:29,891 - discord.client - INFO - logging in using static token
2023-07-18 18:15:31,307 - discord.gateway - INFO - Shard ID None has connected to Gateway (Session ID: 86a4245b9fa3f6556945410398dd69c8).
2023-07-18 18:15:33,465 - root - INFO - Logged in as Anigay 2.0#7825
2023-07-18 18:17:02,245 - discord.client - INFO - logging in using static token
2023-07-18 18:17:03,622 - discord.gateway - INFO - Shard ID None has connected to Gateway (Session ID: b7368050103267239f9f1e0401bb8f6f).
2023-07-18 18:17:05,830 - root - INFO - Logged in as Anigay 2.0#7825
2023-07-18 18:19:43,984 - discord.client - INFO - logging in using static token
2023-07-18 18:19:45,413 - discord.gateway - INFO - Shard ID None has connected to Gateway (Session ID: f19312670188eeb6321ad21c5cac6240).
2023-07-18 18:19:45,881 - discord.ext.commands.bot - ERROR - Ignoring exception in command None
discord.ext.commands.errors.CommandNotFound: Command "bt" is not found
2023-07-18 18:19:47,558 - root - INFO - Logged in as Anigay 2.0#7825
2023-07-18 18:21:39,968 - discord.client - INFO - logging in using static token
2023-07-18 18:21:41,389 - discord.gateway - INFO - Shard ID None has connected to Gateway (Session ID: 716fda8342ce34dcaac6473adf761652).
2023-07-18 18:21:42,737 - discord.ext.commands.bot - ERROR - Ignoring exception in command None
discord.ext.commands.errors.CommandNotFound: Command "bt" is not found
2023-07-18 18:21:43,584 - root - INFO - Logged in as Anigay 2.0#7825
2023-07-18 18:23:17,920 - discord.client - INFO - logging in using static token
2023-07-18 18:23:19,141 - discord.gateway - INFO - Shard ID None has connected to Gateway (Session ID: 4b16f6fdad2353a735f40f34ed7c544b).
2023-07-18 18:23:21,292 - root - INFO - Logged in as Anigay 2.0#7825
2023-07-18 18:24:56,688 - discord.client - INFO - logging in using static token
2023-07-18 18:24:57,996 - discord.gateway - INFO - Shard ID None has connected to Gateway (Session ID: de8c91cabed1a3218915a80d45ea75ae).
2023-07-18 18:24:59,226 - discord.ext.commands.bot - ERROR - Ignoring exception in command None
discord.ext.commands.errors.CommandNotFound: Command "bt" is not found
2023-07-18 18:25:00,193 - root - INFO - Logged in as Anigay 2.0#7825
2023-07-18 18:25:25,268 - asyncio - ERROR - Exception in callback Future.set_result(<sqlite3.Curs...x7fa712426bc0>)
handle: <Handle Future.set_result(<sqlite3.Curs...x7fa712426bc0>)>
Traceback (most recent call last):
  File "/usr/lib/python3.10/asyncio/runners.py", line 44, in run
    return loop.run_until_complete(main)
  File "/usr/lib/python3.10/asyncio/base_events.py", line 633, in run_until_complete
    self.run_forever()
  File "/usr/lib/python3.10/asyncio/base_events.py", line 600, in run_forever
    self._run_once()
  File "/usr/lib/python3.10/asyncio/base_events.py", line 1860, in _run_once
    event_list = self._selector.select(timeout)
  File "/usr/lib/python3.10/selectors.py", line 469, in select
    fd_event_list = self._selector.poll(timeout, max_ev)
KeyboardInterrupt

During handling of the above exception, another exception occurred:

Traceback (most recent call last):
  File "/usr/lib/python3.10/asyncio/events.py", line 80, in _run
    self._context.run(self._callback, *self._args)
asyncio.exceptions.InvalidStateError: invalid state
2023-07-18 18:25:25,840 - discord.client - INFO - logging in using static token
2023-07-18 18:25:27,101 - discord.gateway - INFO - Shard ID None has connected to Gateway (Session ID: 65cbe5fbb8db1a8bf945baa2ab44d4fa).
2023-07-18 18:25:28,410 - discord.ext.commands.bot - ERROR - Ignoring exception in command None
discord.ext.commands.errors.CommandNotFound: Command "bt" is not found
2023-07-18 18:25:29,278 - root - INFO - Logged in as Anigay 2.0#7825
2023-07-18 18:31:07,133 - discord.client - INFO - logging in using static token
2023-07-18 18:31:08,481 - discord.gateway - INFO - Shard ID None has connected to Gateway (Session ID: 1ae81934efb1664687e924e08d5d080f).
2023-07-18 18:31:10,684 - root - INFO - Logged in as Anigay 2.0#7825
2023-07-18 18:32:38,461 - discord.client - INFO - logging in using static token
2023-07-18 18:32:39,720 - discord.gateway - INFO - Shard ID None has connected to Gateway (Session ID: 0d46c8a8888dcaf9d21d80fa5588ec49).
2023-07-18 18:32:41,944 - root - INFO - Logged in as Anigay 2.0#7825
2023-07-18 20:11:21,158 - discord.gateway - INFO - Shard ID None session has been invalidated.
2023-07-18 20:11:26,851 - discord.gateway - INFO - Shard ID None has connected to Gateway (Session ID: 94fd8b367feb9414093f5ac591d2537a).
2023-07-18 20:11:29,018 - root - INFO - Logged in as Anigay 2.0#7825
2023-07-18 20:11:29,019 - discord.client - ERROR - Ignoring exception in on_ready
Traceback (most recent call last):
  File "/home/iceman/.local/lib/python3.10/site-packages/discord/client.py", line 441, in _run_event
    await coro(*args, **kwargs)
  File "/home/iceman/___/Anigay-2.0/src/Anigay.py", line 37, in on_ready
    await bot.add_cog(Debug(bot))
  File "/home/iceman/.local/lib/python3.10/site-packages/discord/ext/commands/bot.py", line 777, in add_cog
    raise discord.ClientException(f'Cog named {cog_name!r} already loaded')
discord.errors.ClientException: Cog named 'Debug' already loaded
2023-07-18 21:14:42,027 - discord.client - INFO - logging in using static token
2023-07-18 21:14:43,089 - discord.gateway - INFO - Shard ID None has connected to Gateway (Session ID: 778460769e6236757aa9d1bfecd6e0d5).
2023-07-18 21:14:45,201 - root - INFO - Logged in as Anigay 2.0#7825
2023-07-18 21:15:31,496 - discord.client - INFO - logging in using static token
2023-07-18 21:15:32,910 - discord.gateway - INFO - Shard ID None has connected to Gateway (Session ID: 79e0a7f44ad37b8623acc209c695617b).
2023-07-18 21:15:35,042 - root - INFO - Logged in as Anigay 2.0#7825
2023-07-18 21:16:09,608 - discord.client - INFO - logging in using static token
2023-07-18 21:16:10,486 - discord.gateway - INFO - Shard ID None has connected to Gateway (Session ID: ce93abcf91a6af8c8da2ac0138f9307f).
2023-07-18 21:16:12,595 - root - INFO - Logged in as Anigay 2.0#7825
2023-07-18 21:23:09,104 - discord.ext.commands.bot - ERROR - Ignoring exception in command None
discord.ext.commands.errors.CommandNotFound: Command "rd" is not found
2023-07-18 21:23:24,471 - discord.ext.commands.bot - ERROR - Ignoring exception in command None
discord.ext.commands.errors.CommandNotFound: Command "rd" is not found
2023-07-18 21:23:34,122 - discord.ext.commands.bot - ERROR - Ignoring exception in command None
discord.ext.commands.errors.CommandNotFound: Command "team" is not found
2023-07-18 21:23:44,943 - discord.ext.commands.bot - ERROR - Ignoring exception in command None
discord.ext.commands.errors.CommandNotFound: Command "team" is not found
2023-07-18 21:23:57,130 - discord.ext.commands.bot - ERROR - Ignoring exception in command None
discord.ext.commands.errors.CommandNotFound: Command "rd" is not found
2023-07-18 21:24:50,582 - discord.ext.commands.bot - ERROR - Ignoring exception in command None
discord.ext.commands.errors.CommandNotFound: Command "rh" is not found
2023-07-18 21:25:05,080 - discord.ext.commands.bot - ERROR - Ignoring exception in command None
discord.ext.commands.errors.CommandNotFound: Command "rh" is not found
2023-07-18 21:29:28,702 - discord.ext.commands.bot - ERROR - Ignoring exception in command None
discord.ext.commands.errors.CommandNotFound: Command "rd" is not found
2023-07-18 21:29:32,947 - discord.ext.commands.bot - ERROR - Ignoring exception in command None
discord.ext.commands.errors.CommandNotFound: Command "rh" is not found
2023-07-18 21:29:38,737 - discord.ext.commands.bot - ERROR - Ignoring exception in command None
discord.ext.commands.errors.CommandNotFound: Command "rh" is not found
2023-07-18 21:31:32,606 - discord.ext.commands.bot - ERROR - Ignoring exception in command None
discord.ext.commands.errors.CommandNotFound: Command "rd" is not found
2023-07-18 21:37:11,551 - discord.ext.commands.bot - ERROR - Ignoring exception in command None
discord.ext.commands.errors.CommandNotFound: Command "rd" is not found
2023-07-18 21:38:12,374 - discord.client - INFO - logging in using static token
2023-07-18 21:38:13,810 - discord.gateway - INFO - Shard ID None has connected to Gateway (Session ID: 760a982e95d2c3f23552df7aa5336e94).
2023-07-18 21:38:15,926 - root - INFO - Logged in as Anigay 2.0#7825
2023-07-18 21:38:45,968 - discord.ext.commands.bot - ERROR - Ignoring exception in command None
discord.ext.commands.errors.CommandNotFound: Command "rd" is not found
2023-07-18 21:38:48,674 - discord.ext.commands.bot - ERROR - Ignoring exception in command None
discord.ext.commands.errors.CommandNotFound: Command "rh" is not found
2023-07-18 21:41:16,889 - discord.client - INFO - logging in using static token
2023-07-18 21:41:18,336 - discord.gateway - INFO - Shard ID None has connected to Gateway (Session ID: 4cc113a45eae3742e496b3e818f8d5f6).
2023-07-18 21:41:20,470 - root - INFO - Logged in as Anigay 2.0#7825
2023-07-18 21:42:42,026 - discord.client - INFO - logging in using static token
2023-07-18 21:42:43,112 - discord.gateway - INFO - Shard ID None has connected to Gateway (Session ID: 7dde6a13585c27599211842e272ef70b).
2023-07-18 21:42:45,261 - root - INFO - Logged in as Anigay 2.0#7825
2023-07-18 21:43:14,510 - discord.client - INFO - logging in using static token
2023-07-18 21:43:15,653 - discord.gateway - INFO - Shard ID None has connected to Gateway (Session ID: fc24fc26783268b1525382ff3bee6ae0).
2023-07-18 21:43:17,781 - root - INFO - Logged in as Anigay 2.0#7825
2023-07-18 21:45:08,347 - discord.ext.commands.bot - ERROR - Ignoring exception in command inventory
Traceback (most recent call last):
  File "/home/iceman/.local/lib/python3.10/site-packages/discord/ext/commands/core.py", line 235, in wrapped
    ret = await coro(*args, **kwargs)
  File "/home/iceman/___/Anigay-2.0/src/User.py", line 165, in inventory
    await cursor.execute("SELECT * FROM Dex")
  File "/home/iceman/.local/lib/python3.10/site-packages/asqlite/__init__.py", line 210, in execute
    await self._post(self._cursor.execute, sql, parameters)
  File "/home/iceman/.local/lib/python3.10/site-packages/asqlite/__init__.py", line 85, in _call_entry
    result = entry.func(*entry.args, **entry.kwargs)
sqlite3.ProgrammingError: Cannot operate on a closed cursor.

The above exception was the direct cause of the following exception:

Traceback (most recent call last):
  File "/home/iceman/.local/lib/python3.10/site-packages/discord/ext/commands/bot.py", line 1350, in invoke
    await ctx.command.invoke(ctx)
  File "/home/iceman/.local/lib/python3.10/site-packages/discord/ext/commands/core.py", line 1029, in invoke
    await injected(*ctx.args, **ctx.kwargs)  # type: ignore
  File "/home/iceman/.local/lib/python3.10/site-packages/discord/ext/commands/core.py", line 244, in wrapped
    raise CommandInvokeError(exc) from exc
discord.ext.commands.errors.CommandInvokeError: Command raised an exception: ProgrammingError: Cannot operate on a closed cursor.
2023-07-18 21:46:40,182 - asyncio - ERROR - Task was destroyed but it is pending!
task: <Task pending name='discord.py: on_message' coro=<Client._run_event() done, defined at /home/iceman/.local/lib/python3.10/site-packages/discord/client.py:433> wait_for=<Future pending cb=[Task.task_wakeup()]>>
2023-07-18 21:46:40,183 - discord.ext.commands.bot - ERROR - Ignoring exception in command select
Traceback (most recent call last):
  File "/home/iceman/.local/lib/python3.10/site-packages/discord/ext/commands/core.py", line 235, in wrapped
    ret = await coro(*args, **kwargs)
RuntimeError: coroutine ignored GeneratorExit

The above exception was the direct cause of the following exception:

Traceback (most recent call last):
  File "/home/iceman/.local/lib/python3.10/site-packages/discord/ext/commands/bot.py", line 1350, in invoke
    await ctx.command.invoke(ctx)
  File "/home/iceman/.local/lib/python3.10/site-packages/discord/ext/commands/core.py", line 1029, in invoke
    await injected(*ctx.args, **ctx.kwargs)  # type: ignore
  File "/home/iceman/.local/lib/python3.10/site-packages/discord/ext/commands/core.py", line 244, in wrapped
    raise CommandInvokeError(exc) from exc
discord.ext.commands.errors.CommandInvokeError: Command raised an exception: RuntimeError: coroutine ignored GeneratorExit
2023-07-18 21:48:06,957 - asyncio - ERROR - Unclosed client session
client_session: <aiohttp.client.ClientSession object at 0x7f9dc2e48d00>
2023-07-18 21:48:07,754 - discord.client - INFO - logging in using static token
2023-07-18 21:48:13,361 - discord.gateway - INFO - Shard ID None has connected to Gateway (Session ID: 646df9f21a12e7021e4766cc4208e60a).
2023-07-18 21:48:15,471 - root - INFO - Logged in as Anigay 2.0#7825
2023-07-18 21:50:23,320 - asyncio - ERROR - Task was destroyed but it is pending!
task: <Task pending name='discord.py: on_message' coro=<Client._run_event() done, defined at /home/iceman/.local/lib/python3.10/site-packages/discord/client.py:433> wait_for=<Future pending cb=[Task.task_wakeup()]>>
2023-07-18 21:50:23,320 - discord.ext.commands.bot - ERROR - Ignoring exception in command select
Traceback (most recent call last):
  File "/home/iceman/.local/lib/python3.10/site-packages/discord/ext/commands/core.py", line 235, in wrapped
    ret = await coro(*args, **kwargs)
RuntimeError: coroutine ignored GeneratorExit

The above exception was the direct cause of the following exception:

Traceback (most recent call last):
  File "/home/iceman/.local/lib/python3.10/site-packages/discord/ext/commands/bot.py", line 1350, in invoke
    await ctx.command.invoke(ctx)
  File "/home/iceman/.local/lib/python3.10/site-packages/discord/ext/commands/core.py", line 1029, in invoke
    await injected(*ctx.args, **ctx.kwargs)  # type: ignore
  File "/home/iceman/.local/lib/python3.10/site-packages/discord/ext/commands/core.py", line 244, in wrapped
    raise CommandInvokeError(exc) from exc
discord.ext.commands.errors.CommandInvokeError: Command raised an exception: RuntimeError: coroutine ignored GeneratorExit
2023-07-18 21:51:39,543 - discord.client - INFO - logging in using static token
2023-07-18 21:51:40,569 - discord.gateway - INFO - Shard ID None has connected to Gateway (Session ID: 855f8402d6dc1cb1f85b09a6a66ae896).
2023-07-18 21:51:42,656 - root - INFO - Logged in as Anigay 2.0#7825
2023-07-18 21:51:43,527 - discord.ext.commands.bot - ERROR - Ignoring exception in command select
Traceback (most recent call last):
  File "/home/iceman/.local/lib/python3.10/site-packages/discord/ext/commands/core.py", line 235, in wrapped
    ret = await coro(*args, **kwargs)
  File "/home/iceman/___/Anigay-2.0/src/User.py", line 208, in select
    await connection.commit()
  File "/home/iceman/.local/lib/python3.10/site-packages/asqlite/__init__.py", line 381, in commit
    return await self._post(self._conn.commit)
  File "/home/iceman/.local/lib/python3.10/site-packages/asqlite/__init__.py", line 85, in _call_entry
    result = entry.func(*entry.args, **entry.kwargs)
sqlite3.ProgrammingError: Cannot operate on a closed database.

The above exception was the direct cause of the following exception:

Traceback (most recent call last):
  File "/home/iceman/.local/lib/python3.10/site-packages/discord/ext/commands/bot.py", line 1350, in invoke
    await ctx.command.invoke(ctx)
  File "/home/iceman/.local/lib/python3.10/site-packages/discord/ext/commands/core.py", line 1029, in invoke
    await injected(*ctx.args, **ctx.kwargs)  # type: ignore
  File "/home/iceman/.local/lib/python3.10/site-packages/discord/ext/commands/core.py", line 244, in wrapped
    raise CommandInvokeError(exc) from exc
discord.ext.commands.errors.CommandInvokeError: Command raised an exception: ProgrammingError: Cannot operate on a closed database.
2023-07-18 21:51:57,151 - discord.client - INFO - logging in using static token
2023-07-18 21:51:58,128 - discord.gateway - INFO - Shard ID None has connected to Gateway (Session ID: e7f02161c50f843b1f9d476c4fa94fb4).
2023-07-18 21:52:00,216 - root - INFO - Logged in as Anigay 2.0#7825
2023-07-18 21:53:23,535 - asyncio - ERROR - Task was destroyed but it is pending!
task: <Task pending name='discord.py: on_message' coro=<Client._run_event() done, defined at /home/iceman/.local/lib/python3.10/site-packages/discord/client.py:433> wait_for=<Future pending cb=[Task.task_wakeup()]>>
2023-07-18 21:53:23,536 - discord.ext.commands.bot - ERROR - Ignoring exception in command select
Traceback (most recent call last):
  File "/home/iceman/.local/lib/python3.10/site-packages/discord/ext/commands/core.py", line 235, in wrapped
    ret = await coro(*args, **kwargs)
RuntimeError: coroutine ignored GeneratorExit

The above exception was the direct cause of the following exception:

Traceback (most recent call last):
  File "/home/iceman/.local/lib/python3.10/site-packages/discord/ext/commands/bot.py", line 1350, in invoke
    await ctx.command.invoke(ctx)
  File "/home/iceman/.local/lib/python3.10/site-packages/discord/ext/commands/core.py", line 1029, in invoke
    await injected(*ctx.args, **ctx.kwargs)  # type: ignore
  File "/home/iceman/.local/lib/python3.10/site-packages/discord/ext/commands/core.py", line 244, in wrapped
    raise CommandInvokeError(exc) from exc
discord.ext.commands.errors.CommandInvokeError: Command raised an exception: RuntimeError: coroutine ignored GeneratorExit
2023-07-18 21:55:35,651 - asyncio - ERROR - Task was destroyed but it is pending!
task: <Task pending name='discord.py: on_message' coro=<Client._run_event() done, defined at /home/iceman/.local/lib/python3.10/site-packages/discord/client.py:433> wait_for=<Future pending cb=[Task.task_wakeup()]>>
2023-07-18 21:55:35,653 - asyncio - ERROR - Task was destroyed but it is pending!
task: <Task pending name='discord.py: on_message' coro=<Client._run_event() done, defined at /home/iceman/.local/lib/python3.10/site-packages/discord/client.py:433> wait_for=<Future pending cb=[Task.task_wakeup()]>>
2023-07-18 21:55:35,653 - discord.ext.commands.bot - ERROR - Ignoring exception in command select
Traceback (most recent call last):
  File "/home/iceman/.local/lib/python3.10/site-packages/discord/ext/commands/core.py", line 235, in wrapped
    ret = await coro(*args, **kwargs)
RuntimeError: coroutine ignored GeneratorExit

The above exception was the direct cause of the following exception:

Traceback (most recent call last):
  File "/home/iceman/.local/lib/python3.10/site-packages/discord/ext/commands/bot.py", line 1350, in invoke
    await ctx.command.invoke(ctx)
  File "/home/iceman/.local/lib/python3.10/site-packages/discord/ext/commands/core.py", line 1029, in invoke
    await injected(*ctx.args, **ctx.kwargs)  # type: ignore
  File "/home/iceman/.local/lib/python3.10/site-packages/discord/ext/commands/core.py", line 244, in wrapped
    raise CommandInvokeError(exc) from exc
discord.ext.commands.errors.CommandInvokeError: Command raised an exception: RuntimeError: coroutine ignored GeneratorExit
2023-07-18 21:55:35,654 - discord.ext.commands.bot - ERROR - Ignoring exception in command select
Traceback (most recent call last):
  File "/home/iceman/.local/lib/python3.10/site-packages/discord/ext/commands/core.py", line 235, in wrapped
    ret = await coro(*args, **kwargs)
RuntimeError: coroutine ignored GeneratorExit

The above exception was the direct cause of the following exception:

Traceback (most recent call last):
  File "/home/iceman/.local/lib/python3.10/site-packages/discord/ext/commands/bot.py", line 1350, in invoke
    await ctx.command.invoke(ctx)
  File "/home/iceman/.local/lib/python3.10/site-packages/discord/ext/commands/core.py", line 1029, in invoke
    await injected(*ctx.args, **ctx.kwargs)  # type: ignore
  File "/home/iceman/.local/lib/python3.10/site-packages/discord/ext/commands/core.py", line 244, in wrapped
    raise CommandInvokeError(exc) from exc
discord.ext.commands.errors.CommandInvokeError: Command raised an exception: RuntimeError: coroutine ignored GeneratorExit
2023-07-18 21:55:52,551 - asyncio - ERROR - Task was destroyed but it is pending!
task: <Task pending name='discord.py: on_message' coro=<Client._run_event() done, defined at /home/iceman/.local/lib/python3.10/site-packages/discord/client.py:433> wait_for=<Future pending cb=[Task.task_wakeup()]>>
2023-07-18 21:55:52,552 - discord.ext.commands.bot - ERROR - Ignoring exception in command select
Traceback (most recent call last):
  File "/home/iceman/.local/lib/python3.10/site-packages/discord/ext/commands/core.py", line 235, in wrapped
    ret = await coro(*args, **kwargs)
RuntimeError: coroutine ignored GeneratorExit

The above exception was the direct cause of the following exception:

Traceback (most recent call last):
  File "/home/iceman/.local/lib/python3.10/site-packages/discord/ext/commands/bot.py", line 1350, in invoke
    await ctx.command.invoke(ctx)
  File "/home/iceman/.local/lib/python3.10/site-packages/discord/ext/commands/core.py", line 1029, in invoke
    await injected(*ctx.args, **ctx.kwargs)  # type: ignore
  File "/home/iceman/.local/lib/python3.10/site-packages/discord/ext/commands/core.py", line 244, in wrapped
    raise CommandInvokeError(exc) from exc
discord.ext.commands.errors.CommandInvokeError: Command raised an exception: RuntimeError: coroutine ignored GeneratorExit
2023-07-18 21:56:29,879 - discord.client - INFO - logging in using static token
2023-07-18 21:56:31,475 - discord.gateway - INFO - Shard ID None has connected to Gateway (Session ID: 7fcc3c6ca126c09b2c682b9bd361772c).
2023-07-18 21:56:33,549 - root - INFO - Logged in as Anigay 2.0#7825
2023-07-18 21:56:40,175 - asyncio - ERROR - Task was destroyed but it is pending!
task: <Task pending name='discord.py: on_message' coro=<Client._run_event() done, defined at /home/iceman/.local/lib/python3.10/site-packages/discord/client.py:433> wait_for=<Future pending cb=[Task.task_wakeup()]>>
2023-07-18 21:56:40,176 - discord.ext.commands.bot - ERROR - Ignoring exception in command select
Traceback (most recent call last):
  File "/home/iceman/.local/lib/python3.10/site-packages/discord/ext/commands/core.py", line 235, in wrapped
    ret = await coro(*args, **kwargs)
RuntimeError: coroutine ignored GeneratorExit

The above exception was the direct cause of the following exception:

Traceback (most recent call last):
  File "/home/iceman/.local/lib/python3.10/site-packages/discord/ext/commands/bot.py", line 1350, in invoke
    await ctx.command.invoke(ctx)
  File "/home/iceman/.local/lib/python3.10/site-packages/discord/ext/commands/core.py", line 1029, in invoke
    await injected(*ctx.args, **ctx.kwargs)  # type: ignore
  File "/home/iceman/.local/lib/python3.10/site-packages/discord/ext/commands/core.py", line 244, in wrapped
    raise CommandInvokeError(exc) from exc
discord.ext.commands.errors.CommandInvokeError: Command raised an exception: RuntimeError: coroutine ignored GeneratorExit
2023-07-18 21:59:20,423 - discord.client - INFO - logging in using static token
2023-07-18 21:59:29,310 - discord.gateway - INFO - Shard ID None has connected to Gateway (Session ID: 1a8bc7bde1f60c0aba32ee415409f000).
2023-07-18 21:59:31,560 - root - INFO - Logged in as Anigay 2.0#7825
2023-07-18 22:00:12,635 - asyncio - ERROR - Unclosed client session
client_session: <aiohttp.client.ClientSession object at 0x7ff0a431cd00>
2023-07-18 22:00:14,008 - discord.client - INFO - logging in using static token
2023-07-18 22:00:15,273 - discord.gateway - INFO - Shard ID None has connected to Gateway (Session ID: 50b4ab36009b6aab60a13e4c23fe0ea7).
2023-07-18 22:00:17,517 - root - INFO - Logged in as Anigay 2.0#7825
2023-07-18 22:00:54,934 - asyncio - ERROR - Task was destroyed but it is pending!
task: <Task pending name='discord.py: on_message' coro=<Client._run_event() done, defined at /home/iceman/.local/lib/python3.10/site-packages/discord/client.py:433> wait_for=<Future pending cb=[Task.task_wakeup()]>>
2023-07-18 22:00:54,934 - asyncio - ERROR - Task was destroyed but it is pending!
task: <Task pending name='discord.py: on_message' coro=<Client._run_event() done, defined at /home/iceman/.local/lib/python3.10/site-packages/discord/client.py:433> wait_for=<Future pending cb=[Task.task_wakeup()]>>
2023-07-20 16:40:47,483 - discord.client - INFO - logging in using static token
2023-07-20 16:40:48,775 - discord.gateway - INFO - Shard ID None has connected to Gateway (Session ID: 17fc7ee685db34b80b9480c3610675d3).
2023-07-20 16:40:50,992 - root - INFO - Logged in as Anigay 2.0#7825
2023-07-20 16:42:19,886 - discord.client - INFO - logging in using static token
2023-07-20 16:42:21,077 - discord.gateway - INFO - Shard ID None has connected to Gateway (Session ID: 9d5147c9db653677be9b18f3b16653a0).
2023-07-20 16:42:22,825 - discord.ext.commands.bot - ERROR - Ignoring exception in command None
discord.ext.commands.errors.CommandNotFound: Command "bt" is not found
2023-07-20 16:42:23,233 - root - INFO - Logged in as Anigay 2.0#7825
2023-07-20 16:43:10,810 - discord.client - INFO - logging in using static token
2023-07-20 16:43:12,396 - discord.gateway - INFO - Shard ID None has connected to Gateway (Session ID: 5d5e9775c66b7682337f0f3c5b91073f).
2023-07-20 16:43:14,558 - root - INFO - Logged in as Anigay 2.0#7825
2023-07-20 16:50:01,395 - discord.client - INFO - logging in using static token
2023-07-20 16:50:02,914 - discord.gateway - INFO - Shard ID None has connected to Gateway (Session ID: eb06e3177657a4b1182d8b7b141c6721).
2023-07-20 16:50:05,069 - root - INFO - Logged in as Anigay 2.0#7825
2023-07-20 16:51:45,590 - discord.client - INFO - logging in using static token
2023-07-20 16:51:46,952 - discord.gateway - INFO - Shard ID None has connected to Gateway (Session ID: 5c23696cf81fa0c2d4616be0151ba067).
2023-07-20 16:51:49,123 - root - INFO - Logged in as Anigay 2.0#7825
2023-07-20 16:53:25,621 - discord.client - INFO - logging in using static token
2023-07-20 16:53:26,767 - discord.gateway - INFO - Shard ID None has connected to Gateway (Session ID: 343aaa94e868bfc7a894d1c85167dd6c).
2023-07-20 16:53:28,937 - root - INFO - Logged in as Anigay 2.0#7825
2023-07-20 16:53:55,861 - discord.client - INFO - logging in using static token
2023-07-20 16:53:56,946 - discord.gateway - INFO - Shard ID None has connected to Gateway (Session ID: 4ab6787c432ce23f6258171d2d5c42b5).
2023-07-20 16:53:59,225 - root - INFO - Logged in as Anigay 2.0#7825
2023-07-20 16:54:49,923 - discord.client - INFO - logging in using static token
2023-07-20 16:54:50,888 - discord.gateway - INFO - Shard ID None has connected to Gateway (Session ID: 3363474b6d9bfaa7f36fc052f4bc939f).
2023-07-20 16:54:53,082 - root - INFO - Logged in as Anigay 2.0#7825
2023-07-20 16:55:31,728 - discord.client - INFO - logging in using static token
2023-07-20 16:55:35,204 - discord.gateway - INFO - Shard ID None has connected to Gateway (Session ID: 1e0920f285f0403c04790597db297e73).
2023-07-20 16:55:37,340 - root - INFO - Logged in as Anigay 2.0#7825
2023-07-20 17:07:55,993 - discord.gateway - INFO - Shard ID None has successfully RESUMED session 1e0920f285f0403c04790597db297e73.
2023-07-20 17:09:38,994 - discord.client - INFO - logging in using static token
2023-07-20 17:09:40,625 - discord.gateway - INFO - Shard ID None has connected to Gateway (Session ID: 2a2405a6fcf3f8e8f2275769b255b0eb).
2023-07-20 17:09:42,824 - root - INFO - Logged in as Anigay 2.0#7825
2023-07-20 17:12:22,735 - discord.client - INFO - logging in using static token
2023-07-20 17:12:24,665 - discord.gateway - INFO - Shard ID None has connected to Gateway (Session ID: 95625897f71519c94d5040f5ae4142e8).
2023-07-20 17:12:26,474 - discord.ext.commands.bot - ERROR - Ignoring exception in command None
discord.ext.commands.errors.CommandNotFound: Command "bt" is not found
2023-07-20 17:12:26,801 - root - INFO - Logged in as Anigay 2.0#7825
2023-07-20 17:29:40,982 - discord.client - INFO - logging in using static token
2023-07-20 17:29:42,587 - discord.gateway - INFO - Shard ID None has connected to Gateway (Session ID: 5da8340ec9d434e85807f3f598148544).
2023-07-20 17:29:44,772 - root - INFO - Logged in as Anigay 2.0#7825
2023-07-20 17:29:54,974 - discord.ext.commands.bot - ERROR - Ignoring exception in command battle
Traceback (most recent call last):
  File "/home/iceman/.local/lib/python3.10/site-packages/discord/ext/commands/core.py", line 235, in wrapped
    ret = await coro(*args, **kwargs)
  File "/home/iceman/___/Anigay-2.0/src/Game.py", line 786, in battle
    await battleRound(oppo, user_card)
  File "/home/iceman/___/Anigay-2.0/src/Game.py", line 743, in battleRound
    healing = fighter.max_hp * (0.075 * fighter1.regen_stacks) # Healing * stacks
NameError: name 'fighter' is not defined

The above exception was the direct cause of the following exception:

Traceback (most recent call last):
  File "/home/iceman/.local/lib/python3.10/site-packages/discord/ext/commands/bot.py", line 1350, in invoke
    await ctx.command.invoke(ctx)
  File "/home/iceman/.local/lib/python3.10/site-packages/discord/ext/commands/core.py", line 1029, in invoke
    await injected(*ctx.args, **ctx.kwargs)  # type: ignore
  File "/home/iceman/.local/lib/python3.10/site-packages/discord/ext/commands/core.py", line 244, in wrapped
    raise CommandInvokeError(exc) from exc
discord.ext.commands.errors.CommandInvokeError: Command raised an exception: NameError: name 'fighter' is not defined
2023-07-20 17:30:17,194 - discord.client - INFO - logging in using static token
2023-07-20 17:30:18,347 - discord.gateway - INFO - Shard ID None has connected to Gateway (Session ID: 9f9531502b3f5dfb6ba4d3394dba3324).
2023-07-20 17:30:19,766 - discord.ext.commands.bot - ERROR - Ignoring exception in command None
discord.ext.commands.errors.CommandNotFound: Command "bt" is not found
2023-07-20 17:30:20,557 - root - INFO - Logged in as Anigay 2.0#7825
2023-07-20 17:34:06,267 - discord.client - INFO - logging in using static token
2023-07-20 17:34:07,982 - discord.gateway - INFO - Shard ID None has connected to Gateway (Session ID: 589b943cfea2eed628ac8ff61dfa0224).
2023-07-20 17:34:10,276 - root - INFO - Logged in as Anigay 2.0#7825
2023-07-20 17:35:50,342 - discord.client - INFO - logging in using static token
2023-07-20 17:35:51,850 - discord.gateway - INFO - Shard ID None has connected to Gateway (Session ID: 0c08afccf31660a8254f066382e54441).
2023-07-20 17:35:54,072 - root - INFO - Logged in as Anigay 2.0#7825
2023-07-20 17:36:33,566 - discord.gateway - INFO - Shard ID None has successfully RESUMED session 0c08afccf31660a8254f066382e54441.
2023-07-20 17:40:06,777 - discord.client - INFO - logging in using static token
2023-07-20 17:40:07,976 - discord.gateway - INFO - Shard ID None has connected to Gateway (Session ID: 0ee970cbdfdf52fca4c92e2cd0290c75).
2023-07-20 17:40:10,101 - root - INFO - Logged in as Anigay 2.0#7825
2023-07-20 17:42:51,125 - discord.client - INFO - logging in using static token
2023-07-20 17:42:52,557 - discord.gateway - INFO - Shard ID None has connected to Gateway (Session ID: 3f7b3b0974c9f9c1cf18e725a9fa660d).
2023-07-20 17:42:54,764 - root - INFO - Logged in as Anigay 2.0#7825
2023-07-20 17:44:34,007 - discord.client - INFO - logging in using static token
2023-07-20 17:44:35,279 - discord.gateway - INFO - Shard ID None has connected to Gateway (Session ID: fe7c7e812735f0d4d283f7d82b94701f).
2023-07-20 17:44:37,439 - root - INFO - Logged in as Anigay 2.0#7825
2023-07-20 18:39:08,687 - asyncio - ERROR - Unclosed client session
client_session: <aiohttp.client.ClientSession object at 0x7fa820719510>
2023-07-20 18:39:09,921 - discord.client - INFO - logging in using static token
2023-07-20 18:39:11,105 - discord.gateway - INFO - Shard ID None has connected to Gateway (Session ID: 9b363796626c61a101db1a3cef79710b).
2023-07-20 18:39:12,843 - discord.ext.commands.bot - ERROR - Ignoring exception in command None
discord.ext.commands.errors.CommandNotFound: Command "cinfo" is not found
2023-07-20 18:39:13,266 - root - INFO - Logged in as Anigay 2.0#7825
2023-07-20 18:39:19,550 - discord.ext.commands.bot - ERROR - Ignoring exception in command None
discord.ext.commands.errors.CommandNotFound: Command "zinfo" is not found
2023-07-20 18:46:03,759 - discord.gateway - INFO - Shard ID None has successfully RESUMED session 9b363796626c61a101db1a3cef79710b.
2023-07-20 18:52:54,771 - discord.client - INFO - logging in using static token
2023-07-20 18:52:55,660 - discord.gateway - INFO - Shard ID None has connected to Gateway (Session ID: efd670d2cf6821561a04b60e7b35788f).
2023-07-20 18:52:57,737 - root - INFO - Logged in as Anigay 2.0#7825
