2023-07-17 15:30:03,270 - discord.client - INFO - logging in using static token
2023-07-17 15:30:04,924 - discord.gateway - INFO - Shard ID None has connected to Gateway (Session ID: 2e91f616aad6045be79a95772aef159c).
2023-07-17 15:30:07,041 - root - INFO - Logged in as Anigay 2.0#7825
2023-07-17 15:30:11,383 - discord.ext.commands.bot - ERROR - Ignoring exception in command summon
Traceback (most recent call last):
  File "/home/iceman/.local/lib/python3.10/site-packages/discord/ext/commands/core.py", line 235, in wrapped
    ret = await coro(*args, **kwargs)
  File "/home/iceman/___/Anigay-2.0/src/Dev.py", line 37, in summon
    await cursor.execute("SELECT * FROM Users WHERE id=?", (user_id,))
  File "/home/iceman/.local/lib/python3.10/site-packages/asqlite/__init__.py", line 210, in execute
    await self._post(self._cursor.execute, sql, parameters)
  File "/home/iceman/.local/lib/python3.10/site-packages/asqlite/__init__.py", line 85, in _call_entry
    result = entry.func(*entry.args, **entry.kwargs)
sqlite3.OperationalError: no such table: Users

The above exception was the direct cause of the following exception:

Traceback (most recent call last):
  File "/home/iceman/.local/lib/python3.10/site-packages/discord/ext/commands/bot.py", line 1350, in invoke
    await ctx.command.invoke(ctx)
  File "/home/iceman/.local/lib/python3.10/site-packages/discord/ext/commands/core.py", line 1029, in invoke
    await injected(*ctx.args, **ctx.kwargs)  # type: ignore
  File "/home/iceman/.local/lib/python3.10/site-packages/discord/ext/commands/core.py", line 244, in wrapped
    raise CommandInvokeError(exc) from exc
discord.ext.commands.errors.CommandInvokeError: Command raised an exception: OperationalError: no such table: Users
2023-07-17 15:30:41,921 - discord.client - INFO - logging in using static token
2023-07-17 15:30:43,212 - discord.gateway - INFO - Shard ID None has connected to Gateway (Session ID: 9c54ff9462970e013efeebc00f68fa8c).
2023-07-17 15:30:45,307 - root - INFO - Logged in as Anigay 2.0#7825
2023-07-17 15:30:50,283 - discord.ext.commands.bot - ERROR - Ignoring exception in command summon
Traceback (most recent call last):
  File "/home/iceman/.local/lib/python3.10/site-packages/discord/ext/commands/core.py", line 235, in wrapped
    ret = await coro(*args, **kwargs)
  File "/home/iceman/___/Anigay-2.0/src/Dev.py", line 37, in summon
    await cursor.execute("SELECT * FROM Users WHERE id=?", (user_id,))
  File "/home/iceman/.local/lib/python3.10/site-packages/asqlite/__init__.py", line 210, in execute
    await self._post(self._cursor.execute, sql, parameters)
  File "/home/iceman/.local/lib/python3.10/site-packages/asqlite/__init__.py", line 85, in _call_entry
    result = entry.func(*entry.args, **entry.kwargs)
sqlite3.OperationalError: no such table: Users

The above exception was the direct cause of the following exception:

Traceback (most recent call last):
  File "/home/iceman/.local/lib/python3.10/site-packages/discord/ext/commands/bot.py", line 1350, in invoke
    await ctx.command.invoke(ctx)
  File "/home/iceman/.local/lib/python3.10/site-packages/discord/ext/commands/core.py", line 1029, in invoke
    await injected(*ctx.args, **ctx.kwargs)  # type: ignore
  File "/home/iceman/.local/lib/python3.10/site-packages/discord/ext/commands/core.py", line 244, in wrapped
    raise CommandInvokeError(exc) from exc
discord.ext.commands.errors.CommandInvokeError: Command raised an exception: OperationalError: no such table: Users
2023-07-17 15:31:19,028 - discord.client - INFO - logging in using static token
2023-07-17 15:31:19,966 - discord.gateway - INFO - Shard ID None has connected to Gateway (Session ID: 3e77ce161ed6a5db42395f1d4a064fae).
2023-07-17 15:31:22,073 - root - INFO - Logged in as Anigay 2.0#7825
2023-07-17 15:31:25,556 - discord.ext.commands.bot - ERROR - Ignoring exception in command summon
Traceback (most recent call last):
  File "/home/iceman/.local/lib/python3.10/site-packages/discord/ext/commands/core.py", line 235, in wrapped
    ret = await coro(*args, **kwargs)
  File "/home/iceman/___/Anigay-2.0/src/Dev.py", line 37, in summon
    await cursor.execute("SELECT * FROM Users WHERE id=?", (user_id,))
  File "/home/iceman/.local/lib/python3.10/site-packages/asqlite/__init__.py", line 210, in execute
    await self._post(self._cursor.execute, sql, parameters)
  File "/home/iceman/.local/lib/python3.10/site-packages/asqlite/__init__.py", line 85, in _call_entry
    result = entry.func(*entry.args, **entry.kwargs)
sqlite3.OperationalError: no such table: Users

The above exception was the direct cause of the following exception:

Traceback (most recent call last):
  File "/home/iceman/.local/lib/python3.10/site-packages/discord/ext/commands/bot.py", line 1350, in invoke
    await ctx.command.invoke(ctx)
  File "/home/iceman/.local/lib/python3.10/site-packages/discord/ext/commands/core.py", line 1029, in invoke
    await injected(*ctx.args, **ctx.kwargs)  # type: ignore
  File "/home/iceman/.local/lib/python3.10/site-packages/discord/ext/commands/core.py", line 244, in wrapped
    raise CommandInvokeError(exc) from exc
discord.ext.commands.errors.CommandInvokeError: Command raised an exception: OperationalError: no such table: Users
2023-07-17 15:32:13,681 - discord.client - INFO - logging in using static token
2023-07-17 15:32:14,844 - discord.gateway - INFO - Shard ID None has connected to Gateway (Session ID: f97cfab6666355b97b232e196e7911f1).
2023-07-17 15:32:16,964 - root - INFO - Logged in as Anigay 2.0#7825
2023-07-17 15:32:20,908 - discord.ext.commands.bot - ERROR - Ignoring exception in command summon
Traceback (most recent call last):
  File "/home/iceman/.local/lib/python3.10/site-packages/discord/ext/commands/core.py", line 235, in wrapped
    ret = await coro(*args, **kwargs)
  File "/home/iceman/___/Anigay-2.0/src/Dev.py", line 41, in summon
    if ctx.author.id not in devids:
NameError: name 'devids' is not defined

The above exception was the direct cause of the following exception:

Traceback (most recent call last):
  File "/home/iceman/.local/lib/python3.10/site-packages/discord/ext/commands/bot.py", line 1350, in invoke
    await ctx.command.invoke(ctx)
  File "/home/iceman/.local/lib/python3.10/site-packages/discord/ext/commands/core.py", line 1029, in invoke
    await injected(*ctx.args, **ctx.kwargs)  # type: ignore
  File "/home/iceman/.local/lib/python3.10/site-packages/discord/ext/commands/core.py", line 244, in wrapped
    raise CommandInvokeError(exc) from exc
discord.ext.commands.errors.CommandInvokeError: Command raised an exception: NameError: name 'devids' is not defined
2023-07-17 15:32:58,244 - discord.client - INFO - logging in using static token
2023-07-17 15:32:59,508 - discord.gateway - INFO - Shard ID None has connected to Gateway (Session ID: f42cf3a6f759ee14b349d6fe805c6fde).
2023-07-17 15:33:01,669 - root - INFO - Logged in as Anigay 2.0#7825
2023-07-17 15:33:18,359 - asyncio - ERROR - Task was destroyed but it is pending!
task: <Task pending name='discord.py: on_message' coro=<Client._run_event() done, defined at /home/iceman/.local/lib/python3.10/site-packages/discord/client.py:433> wait_for=<Future pending cb=[Task.task_wakeup()]>>
2023-07-17 15:33:18,359 - discord.ext.commands.bot - ERROR - Ignoring exception in command select
Traceback (most recent call last):
  File "/home/iceman/.local/lib/python3.10/site-packages/discord/ext/commands/core.py", line 235, in wrapped
    ret = await coro(*args, **kwargs)
RuntimeError: coroutine ignored GeneratorExit

The above exception was the direct cause of the following exception:

Traceback (most recent call last):
  File "/home/iceman/.local/lib/python3.10/site-packages/discord/ext/commands/bot.py", line 1350, in invoke
    await ctx.command.invoke(ctx)
  File "/home/iceman/.local/lib/python3.10/site-packages/discord/ext/commands/core.py", line 1029, in invoke
    await injected(*ctx.args, **ctx.kwargs)  # type: ignore
  File "/home/iceman/.local/lib/python3.10/site-packages/discord/ext/commands/core.py", line 244, in wrapped
    raise CommandInvokeError(exc) from exc
discord.ext.commands.errors.CommandInvokeError: Command raised an exception: RuntimeError: coroutine ignored GeneratorExit
2023-07-17 15:34:47,218 - asyncio - ERROR - Task was destroyed but it is pending!
task: <Task pending name='discord.py: on_message' coro=<Client._run_event() done, defined at /home/iceman/.local/lib/python3.10/site-packages/discord/client.py:433> wait_for=<Future pending cb=[Task.task_wakeup()]>>
2023-07-17 15:34:47,219 - discord.ext.commands.bot - ERROR - Ignoring exception in command select
Traceback (most recent call last):
  File "/home/iceman/.local/lib/python3.10/site-packages/discord/ext/commands/core.py", line 235, in wrapped
    ret = await coro(*args, **kwargs)
RuntimeError: coroutine ignored GeneratorExit

The above exception was the direct cause of the following exception:

Traceback (most recent call last):
  File "/home/iceman/.local/lib/python3.10/site-packages/discord/ext/commands/bot.py", line 1350, in invoke
    await ctx.command.invoke(ctx)
  File "/home/iceman/.local/lib/python3.10/site-packages/discord/ext/commands/core.py", line 1029, in invoke
    await injected(*ctx.args, **ctx.kwargs)  # type: ignore
  File "/home/iceman/.local/lib/python3.10/site-packages/discord/ext/commands/core.py", line 244, in wrapped
    raise CommandInvokeError(exc) from exc
discord.ext.commands.errors.CommandInvokeError: Command raised an exception: RuntimeError: coroutine ignored GeneratorExit
2023-07-17 15:35:05,212 - asyncio - ERROR - Task was destroyed but it is pending!
task: <Task pending name='discord.py: on_message' coro=<Client._run_event() done, defined at /home/iceman/.local/lib/python3.10/site-packages/discord/client.py:433> wait_for=<Future pending cb=[Task.task_wakeup()]>>
2023-07-17 15:35:05,212 - discord.ext.commands.bot - ERROR - Ignoring exception in command select
Traceback (most recent call last):
  File "/home/iceman/.local/lib/python3.10/site-packages/discord/ext/commands/core.py", line 235, in wrapped
    ret = await coro(*args, **kwargs)
RuntimeError: coroutine ignored GeneratorExit

The above exception was the direct cause of the following exception:

Traceback (most recent call last):
  File "/home/iceman/.local/lib/python3.10/site-packages/discord/ext/commands/bot.py", line 1350, in invoke
    await ctx.command.invoke(ctx)
  File "/home/iceman/.local/lib/python3.10/site-packages/discord/ext/commands/core.py", line 1029, in invoke
    await injected(*ctx.args, **ctx.kwargs)  # type: ignore
  File "/home/iceman/.local/lib/python3.10/site-packages/discord/ext/commands/core.py", line 244, in wrapped
    raise CommandInvokeError(exc) from exc
discord.ext.commands.errors.CommandInvokeError: Command raised an exception: RuntimeError: coroutine ignored GeneratorExit
2023-07-17 15:35:17,146 - asyncio - ERROR - Task was destroyed but it is pending!
task: <Task pending name='discord.py: on_message' coro=<Client._run_event() done, defined at /home/iceman/.local/lib/python3.10/site-packages/discord/client.py:433> wait_for=<Future pending cb=[Task.task_wakeup()]>>
2023-07-17 15:35:17,147 - discord.ext.commands.bot - ERROR - Ignoring exception in command select
Traceback (most recent call last):
  File "/home/iceman/.local/lib/python3.10/site-packages/discord/ext/commands/core.py", line 235, in wrapped
    ret = await coro(*args, **kwargs)
RuntimeError: coroutine ignored GeneratorExit

The above exception was the direct cause of the following exception:

Traceback (most recent call last):
  File "/home/iceman/.local/lib/python3.10/site-packages/discord/ext/commands/bot.py", line 1350, in invoke
    await ctx.command.invoke(ctx)
  File "/home/iceman/.local/lib/python3.10/site-packages/discord/ext/commands/core.py", line 1029, in invoke
    await injected(*ctx.args, **ctx.kwargs)  # type: ignore
  File "/home/iceman/.local/lib/python3.10/site-packages/discord/ext/commands/core.py", line 244, in wrapped
    raise CommandInvokeError(exc) from exc
discord.ext.commands.errors.CommandInvokeError: Command raised an exception: RuntimeError: coroutine ignored GeneratorExit
2023-07-17 15:35:17,463 - discord.ext.commands.bot - ERROR - Ignoring exception in command inventory
Traceback (most recent call last):
  File "/home/iceman/.local/lib/python3.10/site-packages/discord/ext/commands/core.py", line 235, in wrapped
    ret = await coro(*args, **kwargs)
  File "/home/iceman/___/Anigay-2.0/src/User.py", line 165, in inventory
    await cursor.execute("SELECT * FROM Dex")
  File "/home/iceman/.local/lib/python3.10/site-packages/asqlite/__init__.py", line 210, in execute
    await self._post(self._cursor.execute, sql, parameters)
  File "/home/iceman/.local/lib/python3.10/site-packages/asqlite/__init__.py", line 85, in _call_entry
    result = entry.func(*entry.args, **entry.kwargs)
sqlite3.ProgrammingError: Cannot operate on a closed cursor.

The above exception was the direct cause of the following exception:

Traceback (most recent call last):
  File "/home/iceman/.local/lib/python3.10/site-packages/discord/ext/commands/bot.py", line 1350, in invoke
    await ctx.command.invoke(ctx)
  File "/home/iceman/.local/lib/python3.10/site-packages/discord/ext/commands/core.py", line 1029, in invoke
    await injected(*ctx.args, **ctx.kwargs)  # type: ignore
  File "/home/iceman/.local/lib/python3.10/site-packages/discord/ext/commands/core.py", line 244, in wrapped
    raise CommandInvokeError(exc) from exc
discord.ext.commands.errors.CommandInvokeError: Command raised an exception: ProgrammingError: Cannot operate on a closed cursor.
2023-07-17 15:35:37,786 - discord.client - INFO - logging in using static token
2023-07-17 15:35:38,945 - discord.gateway - INFO - Shard ID None has connected to Gateway (Session ID: 10947a0a2119c092f13c079af648ffd2).
2023-07-17 15:35:41,049 - root - INFO - Logged in as Anigay 2.0#7825
2023-07-17 15:35:42,818 - discord.ext.commands.bot - ERROR - Ignoring exception in command inventory
Traceback (most recent call last):
  File "/home/iceman/.local/lib/python3.10/site-packages/discord/ext/commands/core.py", line 235, in wrapped
    ret = await coro(*args, **kwargs)
  File "/home/iceman/___/Anigay-2.0/src/User.py", line 165, in inventory
    await cursor.execute("SELECT * FROM Dex")
  File "/home/iceman/.local/lib/python3.10/site-packages/asqlite/__init__.py", line 210, in execute
    await self._post(self._cursor.execute, sql, parameters)
  File "/home/iceman/.local/lib/python3.10/site-packages/asqlite/__init__.py", line 85, in _call_entry
    result = entry.func(*entry.args, **entry.kwargs)
sqlite3.ProgrammingError: Cannot operate on a closed cursor.

The above exception was the direct cause of the following exception:

Traceback (most recent call last):
  File "/home/iceman/.local/lib/python3.10/site-packages/discord/ext/commands/bot.py", line 1350, in invoke
    await ctx.command.invoke(ctx)
  File "/home/iceman/.local/lib/python3.10/site-packages/discord/ext/commands/core.py", line 1029, in invoke
    await injected(*ctx.args, **ctx.kwargs)  # type: ignore
  File "/home/iceman/.local/lib/python3.10/site-packages/discord/ext/commands/core.py", line 244, in wrapped
    raise CommandInvokeError(exc) from exc
discord.ext.commands.errors.CommandInvokeError: Command raised an exception: ProgrammingError: Cannot operate on a closed cursor.
2023-07-17 15:35:53,105 - asyncio - ERROR - Task was destroyed but it is pending!
task: <Task pending name='discord.py: on_message' coro=<Client._run_event() done, defined at /home/iceman/.local/lib/python3.10/site-packages/discord/client.py:433> wait_for=<Future pending cb=[Task.task_wakeup()]>>
2023-07-17 15:35:53,105 - discord.ext.commands.bot - ERROR - Ignoring exception in command select
Traceback (most recent call last):
  File "/home/iceman/.local/lib/python3.10/site-packages/discord/ext/commands/core.py", line 235, in wrapped
    ret = await coro(*args, **kwargs)
RuntimeError: coroutine ignored GeneratorExit

The above exception was the direct cause of the following exception:

Traceback (most recent call last):
  File "/home/iceman/.local/lib/python3.10/site-packages/discord/ext/commands/bot.py", line 1350, in invoke
    await ctx.command.invoke(ctx)
  File "/home/iceman/.local/lib/python3.10/site-packages/discord/ext/commands/core.py", line 1029, in invoke
    await injected(*ctx.args, **ctx.kwargs)  # type: ignore
  File "/home/iceman/.local/lib/python3.10/site-packages/discord/ext/commands/core.py", line 244, in wrapped
    raise CommandInvokeError(exc) from exc
discord.ext.commands.errors.CommandInvokeError: Command raised an exception: RuntimeError: coroutine ignored GeneratorExit
