2023-07-17 15:30:03,270 - discord.client - INFO - logging in using static token
2023-07-17 15:30:04,924 - discord.gateway - INFO - Shard ID None has connected to Gateway (Session ID: 2e91f616aad6045be79a95772aef159c).
2023-07-17 15:30:07,041 - root - INFO - Logged in as Anigay 2.0#7825
2023-07-17 15:30:11,383 - discord.ext.commands.bot - ERROR - Ignoring exception in command summon
Traceback (most recent call last):
  File "/home/iceman/.local/lib/python3.10/site-packages/discord/ext/commands/core.py", line 235, in wrapped
    ret = await coro(*args, **kwargs)
  File "/home/iceman/___/Anigay-2.0/src/Dev.py", line 37, in summon
    await cursor.execute("SELECT * FROM Users WHERE id=?", (user_id,))
  File "/home/iceman/.local/lib/python3.10/site-packages/asqlite/__init__.py", line 210, in execute
    await self._post(self._cursor.execute, sql, parameters)
  File "/home/iceman/.local/lib/python3.10/site-packages/asqlite/__init__.py", line 85, in _call_entry
    result = entry.func(*entry.args, **entry.kwargs)
sqlite3.OperationalError: no such table: Users

The above exception was the direct cause of the following exception:

Traceback (most recent call last):
  File "/home/iceman/.local/lib/python3.10/site-packages/discord/ext/commands/bot.py", line 1350, in invoke
    await ctx.command.invoke(ctx)
  File "/home/iceman/.local/lib/python3.10/site-packages/discord/ext/commands/core.py", line 1029, in invoke
    await injected(*ctx.args, **ctx.kwargs)  # type: ignore
  File "/home/iceman/.local/lib/python3.10/site-packages/discord/ext/commands/core.py", line 244, in wrapped
    raise CommandInvokeError(exc) from exc
discord.ext.commands.errors.CommandInvokeError: Command raised an exception: OperationalError: no such table: Users
2023-07-17 15:30:41,921 - discord.client - INFO - logging in using static token
2023-07-17 15:30:43,212 - discord.gateway - INFO - Shard ID None has connected to Gateway (Session ID: 9c54ff9462970e013efeebc00f68fa8c).
2023-07-17 15:30:45,307 - root - INFO - Logged in as Anigay 2.0#7825
2023-07-17 15:30:50,283 - discord.ext.commands.bot - ERROR - Ignoring exception in command summon
Traceback (most recent call last):
  File "/home/iceman/.local/lib/python3.10/site-packages/discord/ext/commands/core.py", line 235, in wrapped
    ret = await coro(*args, **kwargs)
  File "/home/iceman/___/Anigay-2.0/src/Dev.py", line 37, in summon
    await cursor.execute("SELECT * FROM Users WHERE id=?", (user_id,))
  File "/home/iceman/.local/lib/python3.10/site-packages/asqlite/__init__.py", line 210, in execute
    await self._post(self._cursor.execute, sql, parameters)
  File "/home/iceman/.local/lib/python3.10/site-packages/asqlite/__init__.py", line 85, in _call_entry
    result = entry.func(*entry.args, **entry.kwargs)
sqlite3.OperationalError: no such table: Users

The above exception was the direct cause of the following exception:

Traceback (most recent call last):
  File "/home/iceman/.local/lib/python3.10/site-packages/discord/ext/commands/bot.py", line 1350, in invoke
    await ctx.command.invoke(ctx)
  File "/home/iceman/.local/lib/python3.10/site-packages/discord/ext/commands/core.py", line 1029, in invoke
    await injected(*ctx.args, **ctx.kwargs)  # type: ignore
  File "/home/iceman/.local/lib/python3.10/site-packages/discord/ext/commands/core.py", line 244, in wrapped
    raise CommandInvokeError(exc) from exc
discord.ext.commands.errors.CommandInvokeError: Command raised an exception: OperationalError: no such table: Users
2023-07-17 15:31:19,028 - discord.client - INFO - logging in using static token
2023-07-17 15:31:19,966 - discord.gateway - INFO - Shard ID None has connected to Gateway (Session ID: 3e77ce161ed6a5db42395f1d4a064fae).
2023-07-17 15:31:22,073 - root - INFO - Logged in as Anigay 2.0#7825
2023-07-17 15:31:25,556 - discord.ext.commands.bot - ERROR - Ignoring exception in command summon
Traceback (most recent call last):
  File "/home/iceman/.local/lib/python3.10/site-packages/discord/ext/commands/core.py", line 235, in wrapped
    ret = await coro(*args, **kwargs)
  File "/home/iceman/___/Anigay-2.0/src/Dev.py", line 37, in summon
    await cursor.execute("SELECT * FROM Users WHERE id=?", (user_id,))
  File "/home/iceman/.local/lib/python3.10/site-packages/asqlite/__init__.py", line 210, in execute
    await self._post(self._cursor.execute, sql, parameters)
  File "/home/iceman/.local/lib/python3.10/site-packages/asqlite/__init__.py", line 85, in _call_entry
    result = entry.func(*entry.args, **entry.kwargs)
sqlite3.OperationalError: no such table: Users

The above exception was the direct cause of the following exception:

Traceback (most recent call last):
  File "/home/iceman/.local/lib/python3.10/site-packages/discord/ext/commands/bot.py", line 1350, in invoke
    await ctx.command.invoke(ctx)
  File "/home/iceman/.local/lib/python3.10/site-packages/discord/ext/commands/core.py", line 1029, in invoke
    await injected(*ctx.args, **ctx.kwargs)  # type: ignore
  File "/home/iceman/.local/lib/python3.10/site-packages/discord/ext/commands/core.py", line 244, in wrapped
    raise CommandInvokeError(exc) from exc
discord.ext.commands.errors.CommandInvokeError: Command raised an exception: OperationalError: no such table: Users
2023-07-17 15:32:13,681 - discord.client - INFO - logging in using static token
2023-07-17 15:32:14,844 - discord.gateway - INFO - Shard ID None has connected to Gateway (Session ID: f97cfab6666355b97b232e196e7911f1).
2023-07-17 15:32:16,964 - root - INFO - Logged in as Anigay 2.0#7825
2023-07-17 15:32:20,908 - discord.ext.commands.bot - ERROR - Ignoring exception in command summon
Traceback (most recent call last):
  File "/home/iceman/.local/lib/python3.10/site-packages/discord/ext/commands/core.py", line 235, in wrapped
    ret = await coro(*args, **kwargs)
  File "/home/iceman/___/Anigay-2.0/src/Dev.py", line 41, in summon
    if ctx.author.id not in devids:
NameError: name 'devids' is not defined

The above exception was the direct cause of the following exception:

Traceback (most recent call last):
  File "/home/iceman/.local/lib/python3.10/site-packages/discord/ext/commands/bot.py", line 1350, in invoke
    await ctx.command.invoke(ctx)
  File "/home/iceman/.local/lib/python3.10/site-packages/discord/ext/commands/core.py", line 1029, in invoke
    await injected(*ctx.args, **ctx.kwargs)  # type: ignore
  File "/home/iceman/.local/lib/python3.10/site-packages/discord/ext/commands/core.py", line 244, in wrapped
    raise CommandInvokeError(exc) from exc
discord.ext.commands.errors.CommandInvokeError: Command raised an exception: NameError: name 'devids' is not defined
2023-07-17 15:32:58,244 - discord.client - INFO - logging in using static token
2023-07-17 15:32:59,508 - discord.gateway - INFO - Shard ID None has connected to Gateway (Session ID: f42cf3a6f759ee14b349d6fe805c6fde).
2023-07-17 15:33:01,669 - root - INFO - Logged in as Anigay 2.0#7825
2023-07-17 15:33:18,359 - asyncio - ERROR - Task was destroyed but it is pending!
task: <Task pending name='discord.py: on_message' coro=<Client._run_event() done, defined at /home/iceman/.local/lib/python3.10/site-packages/discord/client.py:433> wait_for=<Future pending cb=[Task.task_wakeup()]>>
2023-07-17 15:33:18,359 - discord.ext.commands.bot - ERROR - Ignoring exception in command select
Traceback (most recent call last):
  File "/home/iceman/.local/lib/python3.10/site-packages/discord/ext/commands/core.py", line 235, in wrapped
    ret = await coro(*args, **kwargs)
RuntimeError: coroutine ignored GeneratorExit

The above exception was the direct cause of the following exception:

Traceback (most recent call last):
  File "/home/iceman/.local/lib/python3.10/site-packages/discord/ext/commands/bot.py", line 1350, in invoke
    await ctx.command.invoke(ctx)
  File "/home/iceman/.local/lib/python3.10/site-packages/discord/ext/commands/core.py", line 1029, in invoke
    await injected(*ctx.args, **ctx.kwargs)  # type: ignore
  File "/home/iceman/.local/lib/python3.10/site-packages/discord/ext/commands/core.py", line 244, in wrapped
    raise CommandInvokeError(exc) from exc
discord.ext.commands.errors.CommandInvokeError: Command raised an exception: RuntimeError: coroutine ignored GeneratorExit
2023-07-17 15:34:47,218 - asyncio - ERROR - Task was destroyed but it is pending!
task: <Task pending name='discord.py: on_message' coro=<Client._run_event() done, defined at /home/iceman/.local/lib/python3.10/site-packages/discord/client.py:433> wait_for=<Future pending cb=[Task.task_wakeup()]>>
2023-07-17 15:34:47,219 - discord.ext.commands.bot - ERROR - Ignoring exception in command select
Traceback (most recent call last):
  File "/home/iceman/.local/lib/python3.10/site-packages/discord/ext/commands/core.py", line 235, in wrapped
    ret = await coro(*args, **kwargs)
RuntimeError: coroutine ignored GeneratorExit

The above exception was the direct cause of the following exception:

Traceback (most recent call last):
  File "/home/iceman/.local/lib/python3.10/site-packages/discord/ext/commands/bot.py", line 1350, in invoke
    await ctx.command.invoke(ctx)
  File "/home/iceman/.local/lib/python3.10/site-packages/discord/ext/commands/core.py", line 1029, in invoke
    await injected(*ctx.args, **ctx.kwargs)  # type: ignore
  File "/home/iceman/.local/lib/python3.10/site-packages/discord/ext/commands/core.py", line 244, in wrapped
    raise CommandInvokeError(exc) from exc
discord.ext.commands.errors.CommandInvokeError: Command raised an exception: RuntimeError: coroutine ignored GeneratorExit
2023-07-17 15:35:05,212 - asyncio - ERROR - Task was destroyed but it is pending!
task: <Task pending name='discord.py: on_message' coro=<Client._run_event() done, defined at /home/iceman/.local/lib/python3.10/site-packages/discord/client.py:433> wait_for=<Future pending cb=[Task.task_wakeup()]>>
2023-07-17 15:35:05,212 - discord.ext.commands.bot - ERROR - Ignoring exception in command select
Traceback (most recent call last):
  File "/home/iceman/.local/lib/python3.10/site-packages/discord/ext/commands/core.py", line 235, in wrapped
    ret = await coro(*args, **kwargs)
RuntimeError: coroutine ignored GeneratorExit

The above exception was the direct cause of the following exception:

Traceback (most recent call last):
  File "/home/iceman/.local/lib/python3.10/site-packages/discord/ext/commands/bot.py", line 1350, in invoke
    await ctx.command.invoke(ctx)
  File "/home/iceman/.local/lib/python3.10/site-packages/discord/ext/commands/core.py", line 1029, in invoke
    await injected(*ctx.args, **ctx.kwargs)  # type: ignore
  File "/home/iceman/.local/lib/python3.10/site-packages/discord/ext/commands/core.py", line 244, in wrapped
    raise CommandInvokeError(exc) from exc
discord.ext.commands.errors.CommandInvokeError: Command raised an exception: RuntimeError: coroutine ignored GeneratorExit
2023-07-17 15:35:17,146 - asyncio - ERROR - Task was destroyed but it is pending!
task: <Task pending name='discord.py: on_message' coro=<Client._run_event() done, defined at /home/iceman/.local/lib/python3.10/site-packages/discord/client.py:433> wait_for=<Future pending cb=[Task.task_wakeup()]>>
2023-07-17 15:35:17,147 - discord.ext.commands.bot - ERROR - Ignoring exception in command select
Traceback (most recent call last):
  File "/home/iceman/.local/lib/python3.10/site-packages/discord/ext/commands/core.py", line 235, in wrapped
    ret = await coro(*args, **kwargs)
RuntimeError: coroutine ignored GeneratorExit

The above exception was the direct cause of the following exception:

Traceback (most recent call last):
  File "/home/iceman/.local/lib/python3.10/site-packages/discord/ext/commands/bot.py", line 1350, in invoke
    await ctx.command.invoke(ctx)
  File "/home/iceman/.local/lib/python3.10/site-packages/discord/ext/commands/core.py", line 1029, in invoke
    await injected(*ctx.args, **ctx.kwargs)  # type: ignore
  File "/home/iceman/.local/lib/python3.10/site-packages/discord/ext/commands/core.py", line 244, in wrapped
    raise CommandInvokeError(exc) from exc
discord.ext.commands.errors.CommandInvokeError: Command raised an exception: RuntimeError: coroutine ignored GeneratorExit
2023-07-17 15:35:17,463 - discord.ext.commands.bot - ERROR - Ignoring exception in command inventory
Traceback (most recent call last):
  File "/home/iceman/.local/lib/python3.10/site-packages/discord/ext/commands/core.py", line 235, in wrapped
    ret = await coro(*args, **kwargs)
  File "/home/iceman/___/Anigay-2.0/src/User.py", line 165, in inventory
    await cursor.execute("SELECT * FROM Dex")
  File "/home/iceman/.local/lib/python3.10/site-packages/asqlite/__init__.py", line 210, in execute
    await self._post(self._cursor.execute, sql, parameters)
  File "/home/iceman/.local/lib/python3.10/site-packages/asqlite/__init__.py", line 85, in _call_entry
    result = entry.func(*entry.args, **entry.kwargs)
sqlite3.ProgrammingError: Cannot operate on a closed cursor.

The above exception was the direct cause of the following exception:

Traceback (most recent call last):
  File "/home/iceman/.local/lib/python3.10/site-packages/discord/ext/commands/bot.py", line 1350, in invoke
    await ctx.command.invoke(ctx)
  File "/home/iceman/.local/lib/python3.10/site-packages/discord/ext/commands/core.py", line 1029, in invoke
    await injected(*ctx.args, **ctx.kwargs)  # type: ignore
  File "/home/iceman/.local/lib/python3.10/site-packages/discord/ext/commands/core.py", line 244, in wrapped
    raise CommandInvokeError(exc) from exc
discord.ext.commands.errors.CommandInvokeError: Command raised an exception: ProgrammingError: Cannot operate on a closed cursor.
2023-07-17 15:35:37,786 - discord.client - INFO - logging in using static token
2023-07-17 15:35:38,945 - discord.gateway - INFO - Shard ID None has connected to Gateway (Session ID: 10947a0a2119c092f13c079af648ffd2).
2023-07-17 15:35:41,049 - root - INFO - Logged in as Anigay 2.0#7825
2023-07-17 15:35:42,818 - discord.ext.commands.bot - ERROR - Ignoring exception in command inventory
Traceback (most recent call last):
  File "/home/iceman/.local/lib/python3.10/site-packages/discord/ext/commands/core.py", line 235, in wrapped
    ret = await coro(*args, **kwargs)
  File "/home/iceman/___/Anigay-2.0/src/User.py", line 165, in inventory
    await cursor.execute("SELECT * FROM Dex")
  File "/home/iceman/.local/lib/python3.10/site-packages/asqlite/__init__.py", line 210, in execute
    await self._post(self._cursor.execute, sql, parameters)
  File "/home/iceman/.local/lib/python3.10/site-packages/asqlite/__init__.py", line 85, in _call_entry
    result = entry.func(*entry.args, **entry.kwargs)
sqlite3.ProgrammingError: Cannot operate on a closed cursor.

The above exception was the direct cause of the following exception:

Traceback (most recent call last):
  File "/home/iceman/.local/lib/python3.10/site-packages/discord/ext/commands/bot.py", line 1350, in invoke
    await ctx.command.invoke(ctx)
  File "/home/iceman/.local/lib/python3.10/site-packages/discord/ext/commands/core.py", line 1029, in invoke
    await injected(*ctx.args, **ctx.kwargs)  # type: ignore
  File "/home/iceman/.local/lib/python3.10/site-packages/discord/ext/commands/core.py", line 244, in wrapped
    raise CommandInvokeError(exc) from exc
discord.ext.commands.errors.CommandInvokeError: Command raised an exception: ProgrammingError: Cannot operate on a closed cursor.
2023-07-17 15:35:53,105 - asyncio - ERROR - Task was destroyed but it is pending!
task: <Task pending name='discord.py: on_message' coro=<Client._run_event() done, defined at /home/iceman/.local/lib/python3.10/site-packages/discord/client.py:433> wait_for=<Future pending cb=[Task.task_wakeup()]>>
2023-07-17 15:35:53,105 - discord.ext.commands.bot - ERROR - Ignoring exception in command select
Traceback (most recent call last):
  File "/home/iceman/.local/lib/python3.10/site-packages/discord/ext/commands/core.py", line 235, in wrapped
    ret = await coro(*args, **kwargs)
RuntimeError: coroutine ignored GeneratorExit

The above exception was the direct cause of the following exception:

Traceback (most recent call last):
  File "/home/iceman/.local/lib/python3.10/site-packages/discord/ext/commands/bot.py", line 1350, in invoke
    await ctx.command.invoke(ctx)
  File "/home/iceman/.local/lib/python3.10/site-packages/discord/ext/commands/core.py", line 1029, in invoke
    await injected(*ctx.args, **ctx.kwargs)  # type: ignore
  File "/home/iceman/.local/lib/python3.10/site-packages/discord/ext/commands/core.py", line 244, in wrapped
    raise CommandInvokeError(exc) from exc
discord.ext.commands.errors.CommandInvokeError: Command raised an exception: RuntimeError: coroutine ignored GeneratorExit
2023-07-17 16:09:35,651 - discord.client - INFO - logging in using static token
2023-07-17 16:09:36,773 - discord.gateway - INFO - Shard ID None has connected to Gateway (Session ID: d54af0c79ac3fd06131d19d8583a04dc).
2023-07-17 16:09:38,902 - root - INFO - Logged in as Anigay 2.0#7825
2023-07-17 16:11:03,075 - discord.client - INFO - logging in using static token
2023-07-17 16:11:04,115 - discord.gateway - INFO - Shard ID None has connected to Gateway (Session ID: 32290e91a68cf8550435b30a93ed235a).
2023-07-17 16:11:06,225 - root - INFO - Logged in as Anigay 2.0#7825
2023-07-17 16:11:07,309 - discord.ext.commands.bot - ERROR - Ignoring exception in command battle
Traceback (most recent call last):
  File "/home/iceman/.local/lib/python3.10/site-packages/discord/ext/commands/core.py", line 235, in wrapped
    ret = await coro(*args, **kwargs)
  File "/home/iceman/___/Anigay-2.0/src/Game.py", line 404, in battle
    enemy.ele_mult = calcEleAdvantage(oppo.element, user_card.element)
NameError: name 'enemy' is not defined

The above exception was the direct cause of the following exception:

Traceback (most recent call last):
  File "/home/iceman/.local/lib/python3.10/site-packages/discord/ext/commands/bot.py", line 1350, in invoke
    await ctx.command.invoke(ctx)
  File "/home/iceman/.local/lib/python3.10/site-packages/discord/ext/commands/core.py", line 1029, in invoke
    await injected(*ctx.args, **ctx.kwargs)  # type: ignore
  File "/home/iceman/.local/lib/python3.10/site-packages/discord/ext/commands/core.py", line 244, in wrapped
    raise CommandInvokeError(exc) from exc
discord.ext.commands.errors.CommandInvokeError: Command raised an exception: NameError: name 'enemy' is not defined
2023-07-17 16:11:15,440 - discord.client - INFO - logging in using static token
2023-07-17 16:11:16,334 - discord.gateway - INFO - Shard ID None has connected to Gateway (Session ID: adfb4a9617c304020c381a084ba0f10b).
2023-07-17 16:11:18,441 - root - INFO - Logged in as Anigay 2.0#7825
2023-07-17 16:33:29,154 - discord.gateway - INFO - Shard ID None has successfully RESUMED session adfb4a9617c304020c381a084ba0f10b.
2023-07-17 16:50:05,177 - discord.gateway - INFO - Shard ID None session has been invalidated.
2023-07-17 16:50:10,707 - discord.gateway - INFO - Shard ID None has connected to Gateway (Session ID: 84bab305632aa0bcfb47e019e7f3bd4e).
2023-07-17 16:50:12,913 - root - INFO - Logged in as Anigay 2.0#7825
2023-07-17 16:50:12,914 - discord.client - ERROR - Ignoring exception in on_ready
Traceback (most recent call last):
  File "/home/iceman/.local/lib/python3.10/site-packages/discord/client.py", line 441, in _run_event
    await coro(*args, **kwargs)
  File "/home/iceman/___/Anigay-2.0/src/Anigay.py", line 37, in on_ready
    await bot.add_cog(Debug(bot))
  File "/home/iceman/.local/lib/python3.10/site-packages/discord/ext/commands/bot.py", line 777, in add_cog
    raise discord.ClientException(f'Cog named {cog_name!r} already loaded')
discord.errors.ClientException: Cog named 'Debug' already loaded
2023-07-17 16:57:31,532 - discord.gateway - INFO - Shard ID None has successfully RESUMED session 84bab305632aa0bcfb47e019e7f3bd4e.
2023-07-17 17:08:07,521 - discord.client - INFO - logging in using static token
2023-07-17 17:08:08,731 - discord.gateway - INFO - Shard ID None has connected to Gateway (Session ID: 8158f2591d3e75658c764e4ddd254bc4).
2023-07-17 17:08:10,837 - root - INFO - Logged in as Anigay 2.0#7825
2023-07-17 17:08:47,595 - discord.client - INFO - logging in using static token
2023-07-17 17:08:48,769 - discord.gateway - INFO - Shard ID None has connected to Gateway (Session ID: ce34758838f64a159c9d0b666c64bb74).
2023-07-17 17:08:50,878 - root - INFO - Logged in as Anigay 2.0#7825
2023-07-17 17:09:38,225 - discord.client - INFO - logging in using static token
2023-07-17 17:09:39,492 - discord.gateway - INFO - Shard ID None has connected to Gateway (Session ID: 703fcd761aba6fe34e9ecbc7497abbc6).
2023-07-17 17:09:41,598 - root - INFO - Logged in as Anigay 2.0#7825
2023-07-17 17:16:05,203 - discord.client - INFO - logging in using static token
2023-07-17 17:16:06,532 - discord.gateway - INFO - Shard ID None has connected to Gateway (Session ID: 90fdf7c699a8b08a39f86b6e32e64221).
2023-07-17 17:16:08,736 - root - INFO - Logged in as Anigay 2.0#7825
2023-07-17 17:17:13,404 - discord.client - INFO - logging in using static token
2023-07-17 17:17:14,928 - discord.gateway - INFO - Shard ID None has connected to Gateway (Session ID: e4194fbd7e92afea5313c0e63b9ae7d3).
2023-07-17 17:17:17,090 - root - INFO - Logged in as Anigay 2.0#7825
2023-07-17 17:17:39,487 - discord.ext.commands.bot - ERROR - Ignoring exception in command inventory
Traceback (most recent call last):
  File "/home/iceman/.local/lib/python3.10/site-packages/discord/ext/commands/core.py", line 235, in wrapped
    ret = await coro(*args, **kwargs)
  File "/home/iceman/___/Anigay-2.0/src/User.py", line 165, in inventory
    await cursor.execute("SELECT * FROM Dex")
  File "/home/iceman/.local/lib/python3.10/site-packages/asqlite/__init__.py", line 210, in execute
    await self._post(self._cursor.execute, sql, parameters)
  File "/home/iceman/.local/lib/python3.10/site-packages/asqlite/__init__.py", line 85, in _call_entry
    result = entry.func(*entry.args, **entry.kwargs)
sqlite3.ProgrammingError: Cannot operate on a closed cursor.

The above exception was the direct cause of the following exception:

Traceback (most recent call last):
  File "/home/iceman/.local/lib/python3.10/site-packages/discord/ext/commands/bot.py", line 1350, in invoke
    await ctx.command.invoke(ctx)
  File "/home/iceman/.local/lib/python3.10/site-packages/discord/ext/commands/core.py", line 1029, in invoke
    await injected(*ctx.args, **ctx.kwargs)  # type: ignore
  File "/home/iceman/.local/lib/python3.10/site-packages/discord/ext/commands/core.py", line 244, in wrapped
    raise CommandInvokeError(exc) from exc
discord.ext.commands.errors.CommandInvokeError: Command raised an exception: ProgrammingError: Cannot operate on a closed cursor.
2023-07-17 17:17:45,667 - asyncio - ERROR - Task was destroyed but it is pending!
task: <Task pending name='discord.py: on_message' coro=<Client._run_event() done, defined at /home/iceman/.local/lib/python3.10/site-packages/discord/client.py:433> wait_for=<Future pending cb=[Task.task_wakeup()]>>
2023-07-17 17:17:45,668 - discord.ext.commands.bot - ERROR - Ignoring exception in command select
Traceback (most recent call last):
  File "/home/iceman/.local/lib/python3.10/site-packages/discord/ext/commands/core.py", line 235, in wrapped
    ret = await coro(*args, **kwargs)
RuntimeError: coroutine ignored GeneratorExit

The above exception was the direct cause of the following exception:

Traceback (most recent call last):
  File "/home/iceman/.local/lib/python3.10/site-packages/discord/ext/commands/bot.py", line 1350, in invoke
    await ctx.command.invoke(ctx)
  File "/home/iceman/.local/lib/python3.10/site-packages/discord/ext/commands/core.py", line 1029, in invoke
    await injected(*ctx.args, **ctx.kwargs)  # type: ignore
  File "/home/iceman/.local/lib/python3.10/site-packages/discord/ext/commands/core.py", line 244, in wrapped
    raise CommandInvokeError(exc) from exc
discord.ext.commands.errors.CommandInvokeError: Command raised an exception: RuntimeError: coroutine ignored GeneratorExit
2023-07-17 17:17:47,473 - discord.ext.commands.bot - ERROR - Ignoring exception in command battle
Traceback (most recent call last):
  File "/home/iceman/.local/lib/python3.10/site-packages/discord/ext/commands/core.py", line 235, in wrapped
    ret = await coro(*args, **kwargs)
  File "/home/iceman/___/Anigay-2.0/src/Game.py", line 444, in battle
    await battleRound( user_card, oppo, embed )
TypeError: Game.battle.<locals>.battleRound() takes 2 positional arguments but 3 were given

The above exception was the direct cause of the following exception:

Traceback (most recent call last):
  File "/home/iceman/.local/lib/python3.10/site-packages/discord/ext/commands/bot.py", line 1350, in invoke
    await ctx.command.invoke(ctx)
  File "/home/iceman/.local/lib/python3.10/site-packages/discord/ext/commands/core.py", line 1029, in invoke
    await injected(*ctx.args, **ctx.kwargs)  # type: ignore
  File "/home/iceman/.local/lib/python3.10/site-packages/discord/ext/commands/core.py", line 244, in wrapped
    raise CommandInvokeError(exc) from exc
discord.ext.commands.errors.CommandInvokeError: Command raised an exception: TypeError: Game.battle.<locals>.battleRound() takes 2 positional arguments but 3 were given
2023-07-17 17:18:05,242 - discord.client - INFO - logging in using static token
2023-07-17 17:18:06,528 - discord.gateway - INFO - Shard ID None has connected to Gateway (Session ID: 30f9fe7cebac064d2c0db815259ced70).
2023-07-17 17:18:08,184 - discord.ext.commands.bot - ERROR - Ignoring exception in command None
discord.ext.commands.errors.CommandNotFound: Command "bt" is not found
2023-07-17 17:18:08,701 - root - INFO - Logged in as Anigay 2.0#7825
2023-07-17 17:18:12,895 - discord.ext.commands.bot - ERROR - Ignoring exception in command battle
Traceback (most recent call last):
  File "/home/iceman/.local/lib/python3.10/site-packages/discord/ext/commands/core.py", line 235, in wrapped
    ret = await coro(*args, **kwargs)
  File "/home/iceman/___/Anigay-2.0/src/Game.py", line 444, in battle
    await battleRound( user_card, oppo, embed )
TypeError: Game.battle.<locals>.battleRound() takes 2 positional arguments but 3 were given

The above exception was the direct cause of the following exception:

Traceback (most recent call last):
  File "/home/iceman/.local/lib/python3.10/site-packages/discord/ext/commands/bot.py", line 1350, in invoke
    await ctx.command.invoke(ctx)
  File "/home/iceman/.local/lib/python3.10/site-packages/discord/ext/commands/core.py", line 1029, in invoke
    await injected(*ctx.args, **ctx.kwargs)  # type: ignore
  File "/home/iceman/.local/lib/python3.10/site-packages/discord/ext/commands/core.py", line 244, in wrapped
    raise CommandInvokeError(exc) from exc
discord.ext.commands.errors.CommandInvokeError: Command raised an exception: TypeError: Game.battle.<locals>.battleRound() takes 2 positional arguments but 3 were given
2023-07-17 17:18:27,088 - discord.client - INFO - logging in using static token
2023-07-17 17:18:28,460 - discord.gateway - INFO - Shard ID None has connected to Gateway (Session ID: d105c6fad6238fcbd89b0bc537d6cf26).
2023-07-17 17:18:30,637 - root - INFO - Logged in as Anigay 2.0#7825
2023-07-17 17:22:22,691 - discord.client - INFO - logging in using static token
2023-07-17 17:22:23,869 - discord.gateway - INFO - Shard ID None has connected to Gateway (Session ID: 8d4a0a6a498c820fb234e88f3596b5fa).
2023-07-17 17:22:25,421 - discord.ext.commands.bot - ERROR - Ignoring exception in command None
discord.ext.commands.errors.CommandNotFound: Command "bt" is not found
2023-07-17 17:22:26,061 - root - INFO - Logged in as Anigay 2.0#7825
2023-07-17 17:23:41,566 - discord.client - INFO - logging in using static token
2023-07-17 17:23:42,945 - discord.gateway - INFO - Shard ID None has connected to Gateway (Session ID: 8457ffec65507500ffe6234ecf33d40d).
2023-07-17 17:23:45,151 - root - INFO - Logged in as Anigay 2.0#7825
2023-07-17 17:41:48,084 - discord.gateway - INFO - Shard ID None has successfully RESUMED session 8457ffec65507500ffe6234ecf33d40d.
2023-07-17 18:24:26,098 - discord.gateway - INFO - Shard ID None session has been invalidated.
2023-07-17 18:24:31,658 - discord.gateway - INFO - Shard ID None has connected to Gateway (Session ID: 4dec786f86ebf7291b8671d000b5094a).
2023-07-17 18:24:33,826 - root - INFO - Logged in as Anigay 2.0#7825
2023-07-17 18:24:33,828 - discord.client - ERROR - Ignoring exception in on_ready
Traceback (most recent call last):
  File "/home/iceman/.local/lib/python3.10/site-packages/discord/client.py", line 441, in _run_event
    await coro(*args, **kwargs)
  File "/home/iceman/___/Anigay-2.0/src/Anigay.py", line 37, in on_ready
    await bot.add_cog(Debug(bot))
  File "/home/iceman/.local/lib/python3.10/site-packages/discord/ext/commands/bot.py", line 777, in add_cog
    raise discord.ClientException(f'Cog named {cog_name!r} already loaded')
discord.errors.ClientException: Cog named 'Debug' already loaded
2023-07-17 18:55:34,046 - discord.ext.commands.bot - ERROR - Ignoring exception in command summon
Traceback (most recent call last):
  File "/home/iceman/.local/lib/python3.10/site-packages/discord/ext/commands/core.py", line 235, in wrapped
    ret = await coro(*args, **kwargs)
  File "/home/iceman/___/Anigay-2.0/src/Dev.py", line 78, in summon
    card_index = card_data["dex"]
UnboundLocalError: local variable 'card_data' referenced before assignment

The above exception was the direct cause of the following exception:

Traceback (most recent call last):
  File "/home/iceman/.local/lib/python3.10/site-packages/discord/ext/commands/bot.py", line 1350, in invoke
    await ctx.command.invoke(ctx)
  File "/home/iceman/.local/lib/python3.10/site-packages/discord/ext/commands/core.py", line 1029, in invoke
    await injected(*ctx.args, **ctx.kwargs)  # type: ignore
  File "/home/iceman/.local/lib/python3.10/site-packages/discord/ext/commands/core.py", line 244, in wrapped
    raise CommandInvokeError(exc) from exc
discord.ext.commands.errors.CommandInvokeError: Command raised an exception: UnboundLocalError: local variable 'card_data' referenced before assignment
2023-07-17 18:56:10,296 - discord.ext.commands.bot - ERROR - Ignoring exception in command summon
Traceback (most recent call last):
  File "/home/iceman/.local/lib/python3.10/site-packages/discord/ext/commands/core.py", line 235, in wrapped
    ret = await coro(*args, **kwargs)
  File "/home/iceman/___/Anigay-2.0/src/Dev.py", line 78, in summon
    card_index = card_data["dex"]
UnboundLocalError: local variable 'card_data' referenced before assignment

The above exception was the direct cause of the following exception:

Traceback (most recent call last):
  File "/home/iceman/.local/lib/python3.10/site-packages/discord/ext/commands/bot.py", line 1350, in invoke
    await ctx.command.invoke(ctx)
  File "/home/iceman/.local/lib/python3.10/site-packages/discord/ext/commands/core.py", line 1029, in invoke
    await injected(*ctx.args, **ctx.kwargs)  # type: ignore
  File "/home/iceman/.local/lib/python3.10/site-packages/discord/ext/commands/core.py", line 244, in wrapped
    raise CommandInvokeError(exc) from exc
discord.ext.commands.errors.CommandInvokeError: Command raised an exception: UnboundLocalError: local variable 'card_data' referenced before assignment
2023-07-17 18:56:37,276 - discord.ext.commands.bot - ERROR - Ignoring exception in command inventory
Traceback (most recent call last):
  File "/home/iceman/.local/lib/python3.10/site-packages/discord/ext/commands/core.py", line 235, in wrapped
    ret = await coro(*args, **kwargs)
  File "/home/iceman/___/Anigay-2.0/src/User.py", line 165, in inventory
    await cursor.execute("SELECT * FROM Dex")
  File "/home/iceman/.local/lib/python3.10/site-packages/asqlite/__init__.py", line 210, in execute
    await self._post(self._cursor.execute, sql, parameters)
  File "/home/iceman/.local/lib/python3.10/site-packages/asqlite/__init__.py", line 85, in _call_entry
    result = entry.func(*entry.args, **entry.kwargs)
sqlite3.ProgrammingError: Cannot operate on a closed cursor.

The above exception was the direct cause of the following exception:

Traceback (most recent call last):
  File "/home/iceman/.local/lib/python3.10/site-packages/discord/ext/commands/bot.py", line 1350, in invoke
    await ctx.command.invoke(ctx)
  File "/home/iceman/.local/lib/python3.10/site-packages/discord/ext/commands/core.py", line 1029, in invoke
    await injected(*ctx.args, **ctx.kwargs)  # type: ignore
  File "/home/iceman/.local/lib/python3.10/site-packages/discord/ext/commands/core.py", line 244, in wrapped
    raise CommandInvokeError(exc) from exc
discord.ext.commands.errors.CommandInvokeError: Command raised an exception: ProgrammingError: Cannot operate on a closed cursor.
2023-07-17 19:25:15,126 - discord.gateway - INFO - Shard ID None has successfully RESUMED session 4dec786f86ebf7291b8671d000b5094a.
2023-07-17 19:44:45,358 - discord.gateway - INFO - Shard ID None has successfully RESUMED session 4dec786f86ebf7291b8671d000b5094a.
2023-07-17 20:39:35,284 - discord.gateway - INFO - Shard ID None session has been invalidated.
2023-07-17 20:39:41,200 - discord.gateway - INFO - Shard ID None has connected to Gateway (Session ID: e71f1d534d01a11d494690164c441c79).
2023-07-17 20:39:43,333 - root - INFO - Logged in as Anigay 2.0#7825
2023-07-17 20:39:43,335 - discord.client - ERROR - Ignoring exception in on_ready
Traceback (most recent call last):
  File "/home/iceman/.local/lib/python3.10/site-packages/discord/client.py", line 441, in _run_event
    await coro(*args, **kwargs)
  File "/home/iceman/___/Anigay-2.0/src/Anigay.py", line 37, in on_ready
    await bot.add_cog(Debug(bot))
  File "/home/iceman/.local/lib/python3.10/site-packages/discord/ext/commands/bot.py", line 777, in add_cog
    raise discord.ClientException(f'Cog named {cog_name!r} already loaded')
discord.errors.ClientException: Cog named 'Debug' already loaded
2023-07-17 20:44:55,349 - discord.gateway - INFO - Shard ID None has successfully RESUMED session e71f1d534d01a11d494690164c441c79.
2023-07-18 10:35:15,809 - discord.client - INFO - logging in using static token
2023-07-18 10:35:16,771 - discord.gateway - INFO - Shard ID None has connected to Gateway (Session ID: 540acfd1de4a0bdc72895dcb44810130).
2023-07-18 10:35:18,834 - root - INFO - Logged in as Anigay 2.0#7825
2023-07-18 10:35:26,646 - discord.ext.commands.bot - ERROR - Ignoring exception in command battle
Traceback (most recent call last):
  File "/home/iceman/.local/lib/python3.10/site-packages/discord/ext/commands/core.py", line 235, in wrapped
    ret = await coro(*args, **kwargs)
  File "/home/iceman/___/Anigay-2.0/src/Game.py", line 461, in battle
    await battleRound( oppo, user_card )
  File "/home/iceman/___/Anigay-2.0/src/Game.py", line 439, in battleRound
    fighter2.hp -= dmg
UnboundLocalError: local variable 'dmg' referenced before assignment

The above exception was the direct cause of the following exception:

Traceback (most recent call last):
  File "/home/iceman/.local/lib/python3.10/site-packages/discord/ext/commands/bot.py", line 1350, in invoke
    await ctx.command.invoke(ctx)
  File "/home/iceman/.local/lib/python3.10/site-packages/discord/ext/commands/core.py", line 1029, in invoke
    await injected(*ctx.args, **ctx.kwargs)  # type: ignore
  File "/home/iceman/.local/lib/python3.10/site-packages/discord/ext/commands/core.py", line 244, in wrapped
    raise CommandInvokeError(exc) from exc
discord.ext.commands.errors.CommandInvokeError: Command raised an exception: UnboundLocalError: local variable 'dmg' referenced before assignment
2023-07-18 10:36:48,609 - discord.client - INFO - logging in using static token
2023-07-18 10:36:49,874 - discord.gateway - INFO - Shard ID None has connected to Gateway (Session ID: 3b3bc0b62c1909350477dab7351627b3).
2023-07-18 10:36:51,941 - root - INFO - Logged in as Anigay 2.0#7825
2023-07-18 10:36:53,151 - discord.ext.commands.bot - ERROR - Ignoring exception in command None
discord.ext.commands.errors.CommandNotFound: Command "bt.bt" is not found
2023-07-18 10:36:56,292 - discord.ext.commands.bot - ERROR - Ignoring exception in command battle
Traceback (most recent call last):
  File "/home/iceman/.local/lib/python3.10/site-packages/discord/ext/commands/core.py", line 235, in wrapped
    ret = await coro(*args, **kwargs)
  File "/home/iceman/___/Anigay-2.0/src/Game.py", line 461, in battle
    await battleRound( user_card, oppo )
  File "/home/iceman/___/Anigay-2.0/src/Game.py", line 438, in battleRound
    dmg = int((((fighter1.current_atk*fighter1.atk*10)+638000)/(8.7 * fighter2.df*10)) * fighter1.ele_mult * CRITICAL_MULTIPLIER)
UnboundLocalError: local variable 'CRITICAL_MULTIPLIER' referenced before assignment

The above exception was the direct cause of the following exception:

Traceback (most recent call last):
  File "/home/iceman/.local/lib/python3.10/site-packages/discord/ext/commands/bot.py", line 1350, in invoke
    await ctx.command.invoke(ctx)
  File "/home/iceman/.local/lib/python3.10/site-packages/discord/ext/commands/core.py", line 1029, in invoke
    await injected(*ctx.args, **ctx.kwargs)  # type: ignore
  File "/home/iceman/.local/lib/python3.10/site-packages/discord/ext/commands/core.py", line 244, in wrapped
    raise CommandInvokeError(exc) from exc
discord.ext.commands.errors.CommandInvokeError: Command raised an exception: UnboundLocalError: local variable 'CRITICAL_MULTIPLIER' referenced before assignment
2023-07-18 10:37:54,011 - discord.client - INFO - logging in using static token
2023-07-18 10:37:54,861 - discord.gateway - INFO - Shard ID None has connected to Gateway (Session ID: 31c2c433438d439e4e219674fafb49db).
2023-07-18 10:37:56,913 - root - INFO - Logged in as Anigay 2.0#7825
2023-07-18 10:39:08,386 - discord.client - INFO - logging in using static token
2023-07-18 10:39:09,957 - discord.gateway - INFO - Shard ID None has connected to Gateway (Session ID: 27a2beef31b08490ad523fda503db273).
2023-07-18 10:39:10,470 - discord.ext.commands.bot - ERROR - Ignoring exception in command None
discord.ext.commands.errors.CommandNotFound: Command "bt" is not found
2023-07-18 10:39:12,273 - root - INFO - Logged in as Anigay 2.0#7825
2023-07-18 10:40:12,414 - discord.client - INFO - logging in using static token
2023-07-18 10:40:13,212 - discord.gateway - INFO - Shard ID None has connected to Gateway (Session ID: 4ba3aeaf833b9fae6635f338169a1542).
2023-07-18 10:40:15,279 - root - INFO - Logged in as Anigay 2.0#7825
2023-07-18 12:23:07,316 - discord.client - INFO - logging in using static token
2023-07-18 12:23:08,104 - discord.gateway - INFO - Shard ID None has connected to Gateway (Session ID: 9b930805bcfaa85d3ad51ff4e22a27b7).
2023-07-18 12:23:10,172 - root - INFO - Logged in as Anigay 2.0#7825
2023-07-18 13:15:20,395 - discord.gateway - INFO - Shard ID None session has been invalidated.
2023-07-18 13:15:25,847 - discord.gateway - INFO - Shard ID None has connected to Gateway (Session ID: 06b68b152a6fa33950de4fd78df8698e).
2023-07-18 13:15:27,940 - root - INFO - Logged in as Anigay 2.0#7825
2023-07-18 13:15:27,941 - discord.client - ERROR - Ignoring exception in on_ready
Traceback (most recent call last):
  File "/home/iceman/.local/lib/python3.10/site-packages/discord/client.py", line 441, in _run_event
    await coro(*args, **kwargs)
  File "/home/iceman/___/Anigay-2.0/src/Anigay.py", line 37, in on_ready
    await bot.add_cog(Debug(bot))
  File "/home/iceman/.local/lib/python3.10/site-packages/discord/ext/commands/bot.py", line 777, in add_cog
    raise discord.ClientException(f'Cog named {cog_name!r} already loaded')
discord.errors.ClientException: Cog named 'Debug' already loaded
2023-07-18 13:35:56,625 - discord.client - INFO - logging in using static token
2023-07-18 13:35:57,796 - discord.gateway - INFO - Shard ID None has connected to Gateway (Session ID: c1a725c447ec818de5a37cb27892eb49).
2023-07-18 13:35:59,868 - root - INFO - Logged in as Anigay 2.0#7825
2023-07-18 13:36:01,731 - discord.ext.commands.bot - ERROR - Ignoring exception in command battle
Traceback (most recent call last):
  File "/home/iceman/.local/lib/python3.10/site-packages/discord/ext/commands/core.py", line 235, in wrapped
    ret = await coro(*args, **kwargs)
  File "/home/iceman/___/Anigay-2.0/src/Game.py", line 468, in battle
    embed = displayHP(user_card, player_hp, oppo, enemy_hp, battle_round)
NameError: name 'player_hp' is not defined

The above exception was the direct cause of the following exception:

Traceback (most recent call last):
  File "/home/iceman/.local/lib/python3.10/site-packages/discord/ext/commands/bot.py", line 1350, in invoke
    await ctx.command.invoke(ctx)
  File "/home/iceman/.local/lib/python3.10/site-packages/discord/ext/commands/core.py", line 1029, in invoke
    await injected(*ctx.args, **ctx.kwargs)  # type: ignore
  File "/home/iceman/.local/lib/python3.10/site-packages/discord/ext/commands/core.py", line 244, in wrapped
    raise CommandInvokeError(exc) from exc
discord.ext.commands.errors.CommandInvokeError: Command raised an exception: NameError: name 'player_hp' is not defined
2023-07-18 13:36:34,467 - discord.client - INFO - logging in using static token
2023-07-18 13:36:35,582 - discord.gateway - INFO - Shard ID None has connected to Gateway (Session ID: 923361ce3e9c0cf69360e9750239717a).
2023-07-18 13:36:37,641 - root - INFO - Logged in as Anigay 2.0#7825
2023-07-18 13:37:13,893 - discord.client - INFO - logging in using static token
2023-07-18 13:37:15,007 - discord.gateway - INFO - Shard ID None has connected to Gateway (Session ID: f943c25d1d7b1e2d29fbbff1811e4276).
2023-07-18 13:37:17,076 - root - INFO - Logged in as Anigay 2.0#7825
2023-07-18 13:37:50,311 - discord.client - INFO - logging in using static token
2023-07-18 13:37:51,306 - discord.gateway - INFO - Shard ID None has connected to Gateway (Session ID: 869c44eb76fc2c284208636904d27fff).
2023-07-18 13:37:53,393 - root - INFO - Logged in as Anigay 2.0#7825
2023-07-18 13:38:27,664 - discord.client - INFO - logging in using static token
2023-07-18 13:38:28,624 - discord.gateway - INFO - Shard ID None has connected to Gateway (Session ID: d823d2666ccfefe0d6ed5a8075a85038).
2023-07-18 13:38:30,695 - root - INFO - Logged in as Anigay 2.0#7825
2023-07-18 13:39:15,875 - discord.client - INFO - logging in using static token
2023-07-18 13:39:16,785 - discord.gateway - INFO - Shard ID None has connected to Gateway (Session ID: c9ddd8ca2445b114559c1e74194a8542).
2023-07-18 13:39:18,863 - root - INFO - Logged in as Anigay 2.0#7825
2023-07-18 13:40:05,353 - discord.client - INFO - logging in using static token
2023-07-18 13:40:06,544 - discord.gateway - INFO - Shard ID None has connected to Gateway (Session ID: 3e492a96017d2f55e99929120f478b5d).
2023-07-18 13:40:08,616 - root - INFO - Logged in as Anigay 2.0#7825
2023-07-18 13:40:42,361 - discord.client - INFO - logging in using static token
2023-07-18 13:40:43,186 - discord.gateway - INFO - Shard ID None has connected to Gateway (Session ID: b31b3d939b1d386e72fab77ce89757b2).
2023-07-18 13:40:45,260 - root - INFO - Logged in as Anigay 2.0#7825
2023-07-18 13:40:57,087 - discord.client - INFO - logging in using static token
2023-07-18 13:40:58,037 - discord.gateway - INFO - Shard ID None has connected to Gateway (Session ID: 684ae45574ab4603ee15002f230d1428).
2023-07-18 13:41:00,129 - root - INFO - Logged in as Anigay 2.0#7825
2023-07-18 13:41:57,722 - discord.client - INFO - logging in using static token
2023-07-18 13:41:58,496 - discord.gateway - INFO - Shard ID None has connected to Gateway (Session ID: 8e53deefc8cc2591f4207ddd853094dc).
2023-07-18 13:42:00,572 - root - INFO - Logged in as Anigay 2.0#7825
2023-07-18 13:42:03,341 - discord.ext.commands.bot - ERROR - Ignoring exception in command battle
Traceback (most recent call last):
  File "/home/iceman/.local/lib/python3.10/site-packages/discord/ext/commands/core.py", line 235, in wrapped
    ret = await coro(*args, **kwargs)
  File "/home/iceman/___/Anigay-2.0/src/Game.py", line 518, in battle
    await battleRound( user_card, oppo )
  File "/home/iceman/___/Anigay-2.0/src/Game.py", line 484, in battleRound
    applyTalent( fighter1, fighter2, battle_round )
  File "/home/iceman/___/Anigay-2.0/src/Game.py", line 38, in applyTalent
    if fighter.rarity_s == "SR":
NameError: name 'fighter' is not defined

The above exception was the direct cause of the following exception:

Traceback (most recent call last):
  File "/home/iceman/.local/lib/python3.10/site-packages/discord/ext/commands/bot.py", line 1350, in invoke
    await ctx.command.invoke(ctx)
  File "/home/iceman/.local/lib/python3.10/site-packages/discord/ext/commands/core.py", line 1029, in invoke
    await injected(*ctx.args, **ctx.kwargs)  # type: ignore
  File "/home/iceman/.local/lib/python3.10/site-packages/discord/ext/commands/core.py", line 244, in wrapped
    raise CommandInvokeError(exc) from exc
discord.ext.commands.errors.CommandInvokeError: Command raised an exception: NameError: name 'fighter' is not defined
2023-07-18 13:42:27,364 - discord.client - INFO - logging in using static token
2023-07-18 13:42:28,354 - discord.gateway - INFO - Shard ID None has connected to Gateway (Session ID: e53ef35ed228a6211762feaf537fc212).
2023-07-18 13:42:30,416 - root - INFO - Logged in as Anigay 2.0#7825
2023-07-18 13:42:46,311 - discord.client - INFO - logging in using static token
2023-07-18 13:42:47,243 - discord.gateway - INFO - Shard ID None has connected to Gateway (Session ID: a9ef37dd427e2e44a2a1292753f01e6b).
2023-07-18 13:42:49,328 - root - INFO - Logged in as Anigay 2.0#7825
2023-07-18 13:43:54,276 - discord.client - INFO - logging in using static token
2023-07-18 13:43:55,227 - discord.gateway - INFO - Shard ID None has connected to Gateway (Session ID: 4f98c5a178ed5f2375409bc181647bc2).
2023-07-18 13:43:57,315 - root - INFO - Logged in as Anigay 2.0#7825
2023-07-18 13:47:12,607 - discord.client - INFO - logging in using static token
2023-07-18 13:47:13,514 - discord.gateway - INFO - Shard ID None has connected to Gateway (Session ID: b17ed331514dea6b4d4c1ad32c3fd6d2).
2023-07-18 13:47:15,588 - root - INFO - Logged in as Anigay 2.0#7825
2023-07-18 13:49:59,244 - discord.client - INFO - logging in using static token
2023-07-18 13:50:00,250 - discord.gateway - INFO - Shard ID None has connected to Gateway (Session ID: 8019e777229b6407dc727c43c6887f62).
2023-07-18 13:50:02,336 - root - INFO - Logged in as Anigay 2.0#7825
2023-07-18 13:50:08,120 - asyncio - ERROR - Exception in callback Future.set_result(None)
handle: <Handle Future.set_result(None)>
Traceback (most recent call last):
  File "/usr/lib/python3.10/asyncio/runners.py", line 44, in run
    return loop.run_until_complete(main)
  File "/usr/lib/python3.10/asyncio/base_events.py", line 633, in run_until_complete
    self.run_forever()
  File "/usr/lib/python3.10/asyncio/base_events.py", line 600, in run_forever
    self._run_once()
  File "/usr/lib/python3.10/asyncio/base_events.py", line 1860, in _run_once
    event_list = self._selector.select(timeout)
  File "/usr/lib/python3.10/selectors.py", line 469, in select
    fd_event_list = self._selector.poll(timeout, max_ev)
KeyboardInterrupt

During handling of the above exception, another exception occurred:

Traceback (most recent call last):
  File "/usr/lib/python3.10/asyncio/events.py", line 80, in _run
    self._context.run(self._callback, *self._args)
asyncio.exceptions.InvalidStateError: invalid state
2023-07-18 13:50:10,456 - discord.client - INFO - logging in using static token
2023-07-18 13:50:11,618 - discord.gateway - INFO - Shard ID None has connected to Gateway (Session ID: cebac769f87515dbcebb7b6757bac640).
2023-07-18 13:50:13,676 - root - INFO - Logged in as Anigay 2.0#7825
2023-07-18 13:56:06,010 - discord.client - INFO - logging in using static token
2023-07-18 13:56:07,052 - discord.gateway - INFO - Shard ID None has connected to Gateway (Session ID: fbb75ca5d5f5ade0037b6ad844805ca4).
2023-07-18 13:56:09,111 - root - INFO - Logged in as Anigay 2.0#7825
2023-07-18 13:57:07,517 - discord.client - INFO - logging in using static token
2023-07-18 13:57:09,618 - discord.gateway - INFO - Shard ID None has connected to Gateway (Session ID: a60c81d939125cb7ed4fed69ebe43e8f).
2023-07-18 13:57:12,242 - root - INFO - Logged in as Anigay 2.0#7825
2023-07-18 13:57:48,360 - discord.client - INFO - logging in using static token
2023-07-18 13:57:52,104 - discord.gateway - INFO - Shard ID None has connected to Gateway (Session ID: c6664004424776af240671beee35ab14).
2023-07-18 13:57:54,185 - root - INFO - Logged in as Anigay 2.0#7825
2023-07-18 13:59:28,560 - discord.client - INFO - logging in using static token
2023-07-18 13:59:31,025 - discord.gateway - INFO - Shard ID None has connected to Gateway (Session ID: 09dfe190584571d1ef27f34d7c5f8bbe).
2023-07-18 13:59:33,104 - root - INFO - Logged in as Anigay 2.0#7825
2023-07-18 14:04:41,534 - discord.client - INFO - logging in using static token
2023-07-18 14:04:42,846 - discord.gateway - INFO - Shard ID None has connected to Gateway (Session ID: c33f9c40d845b4d3ac0d9ea1cb54cfd9).
2023-07-18 14:04:44,923 - root - INFO - Logged in as Anigay 2.0#7825
